Workbook
Name NEB_Ultra_II_RNA: #REF!

Sheet INPUTS
Q1: =SUM(Q6:Q69) -> 660 | R1: total
B2: paste from QC sheet | D2: =INPUTS!M6&":" -> : | O2: if available
D3: Final Library (smear-adjusted: 185-210bp) | K3: Calculated | O3: Empirical | P3: Use
B4: Lib | D4: Final | E4: Total | F4: Barcodes | I4: lowMW=primer | J4: AdDimer | K4: Library | L4: Total | N4: library | O4: Library | P4: Library | Q4: Target
A5: Project# | B5: Name | C5: RNA | D5: ng/ul | E5: vol | F5: UDI: Plate_Well | G5: notes | H5: Adj peak size | I5: %ofLib | J5: nM | K5: nM | L5: nM | M5: final# | N5: storage | O5: nM | P5: nM | Q5: Reads (M)
A6: 7050I | B6: EF19 | C6: T1 | D6: 1.7766 | E6: 20 | F6: P4_A05 | H6: 198 | K6: =D6/(H6*660)*1000000 -> 13.595041 | L6: =K6 -> 13.595041 | O6: nd | P6: =IF(ISNUMBER(O6),O6,K6) -> 13.595041 | Q6: 100
A7: 7050I | B7: EF20 | C7: T2 | D7: 1.70372 | E7: 20 | F7: P4_B05 | H7: 198 | K7: =D7/(H7*660)*1000000 -> 13.037343 | L7: =K7 -> 13.037343 | O7: nd | P7: =IF(ISNUMBER(O7),O7,K7) -> 13.037343 | Q7: 10
A8: 7050I | B8: EF21 | C8: T3 | D8: 1.61175 | E8: 20 | F8: P4_C05 | H8: 198 | K8: =D8/(H8*660)*1000000 -> 12.333563 | L8: =K8 -> 12.333563 | O8: nd | P8: =IF(ISNUMBER(O8),O8,K8) -> 12.333563 | Q8: 100
A9: 7050I | B9: EF22 | C9: B1 | D9: 2.27232 | E9: 20 | F9: P4_D05 | H9: 196 | K9: =D9/(H9*660)*1000000 -> 17.565863 | L9: =K9 -> 17.565863 | O9: nd | P9: =IF(ISNUMBER(O9),O9,K9) -> 17.565863 | Q9: 10
A10: 7050I | B10: EF23 | C10: B2 | D10: 2.45575 | E10: 20 | F10: P4_E05 | H10: 198 | K10: =D10/(H10*660)*1000000 -> 18.792088 | L10: =K10 -> 18.792088 | O10: nd | P10: =IF(ISNUMBER(O10),O10,K10) -> 18.792088 | Q10: 100
A11: 7050I | B11: EF24 | C11: B3 | D11: 2.39632 | E11: 20 | F11: P4_F05 | H11: 198 | K11: =D11/(H11*660)*1000000 -> 18.337313 | L11: =K11 -> 18.337313 | O11: nd | P11: =IF(ISNUMBER(O11),O11,K11) -> 18.337313 | Q11: 10
A12: 7050I | B12: EF25 | C12: T1 | D12: 2.53 | E12: 20 | F12: P4_A06 | H12: 199 | K12: =D12/(H12*660)*1000000 -> 19.262982 | L12: =K12 -> 19.262982 | O12: nd | P12: =IF(ISNUMBER(O12),O12,K12) -> 19.262982 | Q12: 100
A13: 7050I | B13: EF26 | C13: T2 | D13: 3.3 | E13: 20 | F13: P4_B06 | H13: 198 | K13: =D13/(H13*660)*1000000 -> 25.252525 | L13: =K13 -> 25.252525 | O13: nd | P13: =IF(ISNUMBER(O13),O13,K13) -> 25.252525 | Q13: 10
A14: 7050I | B14: EF27 | C14: T3 | D14: 3.1212 | E14: 20 | F14: P4_C06 | H14: 197 | K14: =D14/(H14*660)*1000000 -> 24.005538 | L14: =K14 -> 24.005538 | O14: nd | P14: =IF(ISNUMBER(O14),O14,K14) -> 24.005538 | Q14: 100
A15: 7050I | B15: EF28 | C15: B1 | D15: 0.1 | E15: 20 | F15: P4_D06 | H15: 198 | K15: =D15/(H15*660)*1000000 -> 0.76522804 | L15: =K15 -> 0.76522804 | O15: nd | P15: =IF(ISNUMBER(O15),O15,K15) -> 0.76522804 | Q15: 10
A16: 7050I | B16: EF29 | C16: B2 | D16: 0.1 | E16: 20 | F16: P4_E06 | H16: 196 | K16: =D16/(H16*660)*1000000 -> 0.77303649 | L16: =K16 -> 0.77303649 | O16: nd | P16: =IF(ISNUMBER(O16),O16,K16) -> 0.77303649 | Q16: 100
A17: 7050I | B17: EF30 | C17: B3 | D17: 0.1 | E17: 20 | F17: P4_F06 | H17: 197 | K17: =D17/(H17*660)*1000000 -> 0.76911244 | L17: =K17 -> 0.76911244 | O17: nd | P17: =IF(ISNUMBER(O17),O17,K17) -> 0.76911244 | Q17: 10
O18: nd | P18: =IF(ISNUMBER(O18),O18,K18) -> 0 | Q18: 0
O19: nd | P19: =IF(ISNUMBER(O19),O19,K19) -> 0 | Q19: 0
O20: nd | P20: =IF(ISNUMBER(O20),O20,K20) -> 0 | Q20: 0
O21: nd | P21: =IF(ISNUMBER(O21),O21,K21) -> 0 | Q21: 0
O22: nd | P22: =IF(ISNUMBER(O22),O22,K22) -> 0 | Q22: 0
O23: nd | P23: =IF(ISNUMBER(O23),O23,K23) -> 0 | Q23: 0
O24: nd | P24: =IF(ISNUMBER(O24),O24,K24) -> 0 | Q24: 0
O25: nd | P25: =IF(ISNUMBER(O25),O25,K25) -> 0 | Q25: 0
O26: nd | P26: =IF(ISNUMBER(O26),O26,K26) -> 0 | Q26: 0
O27: nd | P27: =IF(ISNUMBER(O27),O27,K27) -> 0 | Q27: 0
O28: nd | P28: =IF(ISNUMBER(O28),O28,K28) -> 0 | Q28: 0
O29: nd | P29: =IF(ISNUMBER(O29),O29,K29) -> 0 | Q29: 0
... O38: nd | P38: =IF(ISNUMBER(O38),O38,K38) -> 0 | Q38: 0
A39: pooling sheets end here -- add more rows/copy formulas down in Final Pool and Prepool sheets if there are more libraries to add | O39: nd | P39: =IF(ISNUMBER(O39),O39,K39) -> 0 | Q39: 0
O40: nd | P40: =IF(ISNUMBER(O40),O40,K40) -> 0 | Q40: 0
O41: nd | P41: =IF(ISNUMBER(O41),O41,K41) -> 0 | Q41: 0
O42: nd | P42: =IF(ISNUMBER(O42),O42,K42) -> 0 | Q42: 0
O43: nd | P43: =IF(ISNUMBER(O43),O43,K43) -> 0 | Q43: 0
O44: nd | P44: =IF(ISNUMBER(O44),O44,K44) -> 0 | Q44: 0
O45: nd | P45: =IF(ISNUMBER(O45),O45,K45) -> 0 | Q45: 0
O46: nd | P46: =IF(ISNUMBER(O46),O46,K46) -> 0 | Q46: 0
O47: nd | P47: =IF(ISNUMBER(O47),O47,K47) -> 0 | Q47: 0
O48: nd | P48: =IF(ISNUMBER(O48),O48,K48) -> 0 | Q48: 0
...

Sheet Final Pool
T1: Final Pool | X1: 7050I-miRNA | AJ1: 400 | AK1: M reads per flowcell (min)
A2: Don’t add libraries here -- only add on INPUTS sheet! Filter this sheet for printing (no need to delete rows) | T2: 45982 | Z2: =COUNT(Z6:Z18) -> 1 | AA2: =COUNTIF(AA6:AA18,">2") -> 1 | AF2: =COUNTIF(AF6:AF18,">2") -> 1 | AJ2: =AJ1*(1-$J$22) -> 400 | AK2: M nonAdaptor reads
D3: Final Library | O3: =INPUTS!O3 -> Empirical | P3: =INPUTS!P3 -> Use | R3: AdDimer adjust | X3: Final Lib | AA3: Pool | AK3: yes | AL3: consider prepool
B4: Lib | D4: =INPUTS!D4 -> Final | E4: =INPUTS!E4 -> Total | I4: =INPUTS!I4 -> lowMW=primer | J4: =INPUTS!J4 -> AdDimer | K4: =INPUTS!K4 -> Library | L4: =INPUTS!L4 -> Total | O4: =INPUTS!O4 -> Library | P4: =INPUTS!P4 -> Library | R4: 0.05 | V4: =COUNTIF(W6:W17,">1") -> 0 | Z4: pre-dil | AA4: 0.1 | AC4: pmol (Adj lib) | AG4: target | AK4: formula - select libs on Prepool sheet
A5: Project ID | B5: Name | C5: match | D5: =INPUTS!D5 -> ng/ul | E5: =INPUTS!E5 -> vol | F5: =INPUTS!F5 -> UDI: Plate_Well | G5: =INPUTS!G5 -> notes | H5: =INPUTS!H5 -> Adj peak size | I5: =INPUTS!I5 -> %ofLib | J5: =INPUTS!J5 -> nM | K5: =INPUTS!K5 -> nM | ... Q5: =INPUTS!Q5 -> Reads (M) | R5: Adj lib nM | S5: tot nM | T5: Project# | U5: Lib# | V5: BC | X5: name | Y5: Loc | AA5: vol | AC5: adj lib pmol | AD5: tot pmol | AE5: total ng | AF5: stock vol | AG5: M reads | AH5: adj lib pmol | AI5: % of pool | AJ5: est M reads | AK5: Prepool # | AL5: flowcell | AM5: % of run | AN5: obs/exp | AO5: adj uM
A6: =IF(INPUTS!A6=0,"none",INPUTS!A6) -> 7050I | B6: =IF(INPUTS!B6=0,"none",INPUTS!B6) -> EF19 | C6: =IF(B6="none",0,MATCH(B6,INPUTS!$B$6:$B$69,0)) -> 1 | D6: =IF($C6=0,"",OFFSET(INPUTS!D$5,$C6,0)) -> 1.7766 | E6: =IF($C6=0,"",OFFSET(INPUTS!E$5,$C6,0)) -> 20 | F6: =IF($C6=0,"",OFFSET(INPUTS!F$5,$C6,0)) -> P4_A05 | G6: =IF($C6=0,"",OFFSET(INPUTS!G$5,$C6,0)) -> 0 | H6: =IF($C6=0,"",OFFSET(INPUTS!H$5,$C6,0)) -> 198 | I6: =IF($C6=0,"",OFFSET(INPUTS!I$5,$C6,0)) -> 0 | J6: =IF($C6=0,"",OFFSET(INPUTS!J$5,$C6,0)) -> 0 | K6: =IF($C6=0,"",OFFSET(INPUTS!K$5,$C6,0)) -> 13.595041 | ... Q6: =IF($C6=0,"",OFFSET(INPUTS!Q$5,$C6,0)) -> 100 | R6: =IF($C6=0,"",$P6-($J6*R$4)) -> 13.595041 | S6: =SUM(J6,R6) -> 13.595041 | T6: =IF(A6=0,"",A6) -> 7050I | U6: =IF(M6=0,"",M6) | V6: =IF(F6=0,"",F6&IF(OR(G6="",G6=0),"","+"&G6)) -> P4_A05 | W6: =IF(ISNUMBER(V6),COUNTIF($V$6:$V$17,V6),"") | X6: =$B6 -> EF19 | Z6: =IF($AK6>0,"",IF($R6="","",IF(AF6<0.2,10,IF(AF6<0.795,5,"")))) | AA6: =IF($AK6>0,"in Prepool",IF($R6="","",AF6*IF($Z6="",1,$Z6))) -> in Prepool | AB6: =IF(ISNUMBER(AA6),RANK(AA6,$AA$6:$AA$19,0),"") | AC6: =IF($AK6>0,"",IF($R6="","",R6*$AA6/IF($Z6="",1,$Z6))) | AD6: =IF($AK6>0,"",IF($R6="","",S6*$AA6/IF($Z6="",1,$Z6))) | AE6: =IF($AK6>0,"",IF($R6="","",D6*$AA6/IF($Z6="",1,$Z6))) | AF6: =IF(R6="","",$AA$4/R6*Q6) -> 0.73556231 | AG6: =IF(R6="","",Q6) -> 100 | AH6: =IF(R6="","",R6*AF6) -> 10 | AI6: =IF($AF6="","",AH6/$AH$20) -> 0.15151515 | AJ6: =IF($AF6="","",$AJ$2*AI6) -> 60.606061 | AK6: =IF(SUMIF('Prepool 1'!$X$6:$X$38,X6,'Prepool 1'!$AH$6:$AH$38)=1,1,IF(SUMIF('Prepool 1'!$X$6:$X$38,X6,'Prepool 1'!$AH$6:$AH$38)=0,IF(SUMIF('Prepool 2'!$X$6:$X$38,X6,'Prepool 2'!$AH$6:$AH$38)=1,2,IF(SUMIF('Prepool 2'!$X$6:$X$38,X6,'Prepool 2'!$AH$6:$AH$38)=0,,"ERR")),"ERR")) -> 2 | AM6: =AL6/$AL$20 -> 0 | AN6: =IF($AF6="","",AM6/AI6) -> 0 | AO6: =IF($AF6="","",AN6*R6) -> 0
A7: =IF(INPUTS!A7=0,"none",INPUTS!A7) -> 7050I | B7: =IF(INPUTS!B7=0,"none",INPUTS!B7) -> EF20 | C7: =IF(B7="none",0,MATCH(B7,INPUTS!$B$6:$B$69,0)) -> 2 | D7: =IF($C7=0,"",OFFSET(INPUTS!D$5,$C7,0)) -> 1.70372 | E7: =IF($C7=0,"",OFFSET(INPUTS!E$5,$C7,0)) -> 20 | F7: =IF($C7=0,"",OFFSET(INPUTS!F$5,$C7,0)) -> P4_B05 | G7: =IF($C7=0,"",OFFSET(INPUTS!G$5,$C7,0)) -> 0 | H7: =IF($C7=0,"",OFFSET(INPUTS!H$5,$C7,0)) -> 198 | I7: =IF($C7=0,"",OFFSET(INPUTS!I$5,$C7,0)) -> 0 | J7: =IF($C7=0,"",OFFSET(INPUTS!J$5,$C7,0)) -> 0 | K7: =IF($C7=0,"",OFFSET(INPUTS!K$5,$C7,0)) -> 13.037343 | ... Q7: =IF($C7=0,"",OFFSET(INPUTS!Q$5,$C7,0)) -> 10 | R7: =IF($C7=0,"",$P7-($J7*R$4)) -> 13.037343 | S7: =SUM(J7,R7) -> 13.037343 | T7: =IF(A7=0,"",A7) -> 7050I | U7: =IF(M7=0,"",M7) | V7: =IF(F7=0,"",F7&IF(OR(G7="",G7=0),"","+"&G7)) -> P4_B05 | W7: =IF(ISNUMBER(V7),COUNTIF($V$6:$V$17,V7),"") | X7: =$B7 -> EF20 | Z7: =IF($AK7>0,"",IF($R7="","",IF(AF7<0.2,10,IF(AF7<0.795,5,"")))) | AA7: =IF($AK7>0,"in Prepool",IF($R7="","",AF7*IF($Z7="",1,$Z7))) -> in Prepool | AB7: =IF(ISNUMBER(AA7),RANK(AA7,$AA$6:$AA$19,0),"") | AC7: =IF($AK7>0,"",IF($R7="","",R7*$AA7/IF($Z7="",1,$Z7))) | AD7: =IF($AK7>0,"",IF($R7="","",S7*$AA7/IF($Z7="",1,$Z7))) | AE7: =IF($AK7>0,"",IF($R7="","",D7*$AA7/IF($Z7="",1,$Z7))) | AF7: =IF(R7="","",$AA$4/R7*Q7) -> 0.076702745 | AG7: =IF(R7="","",Q7) -> 10 | AH7: =IF(R7="","",R7*AF7) -> 1 | AI7: =IF($AF7="","",AH7/$AH$20) -> 0.015151515 | AJ7: =IF($AF7="","",$AJ$2*AI7) -> 6.0606061 | AK7: =IF(SUMIF('Prepool 1'!$X$6:$X$38,X7,'Prepool 1'!$AH$6:$AH$38)=1,1,IF(SUMIF('Prepool 1'!$X$6:$X$38,X7,'Prepool 1'!$AH$6:$AH$38)=0,IF(SUMIF('Prepool 2'!$X$6:$X$38,X7,'Prepool 2'!$AH$6:$AH$38)=1,2,IF(SUMIF('Prepool 2'!$X$6:$X$38,X7,'Prepool 2'!$AH$6:$AH$38)=0,,"ERR")),"ERR")) -> 1 | AM7: =AL7/$AL$20 -> 0 | AN7: =IF($AF7="","",AM7/AI7) -> 0 | AO7: =IF($AF7="","",AN7*R7) -> 0
A8: =IF(INPUTS!A8=0,"none",INPUTS!A8) -> 7050I | B8: =IF(INPUTS!B8=0,"none",INPUTS!B8) -> EF21 | C8: =IF(B8="none",0,MATCH(B8,INPUTS!$B$6:$B$69,0)) -> 3 | D8: =IF($C8=0,"",OFFSET(INPUTS!D$5,$C8,0)) -> 1.61175 | E8: =IF($C8=0,"",OFFSET(INPUTS!E$5,$C8,0)) -> 20 | F8: =IF($C8=0,"",OFFSET(INPUTS!F$5,$C8,0)) -> P4_C05 | G8: =IF($C8=0,"",OFFSET(INPUTS!G$5,$C8,0)) -> 0 | H8: =IF($C8=0,"",OFFSET(INPUTS!H$5,$C8,0)) -> 198 | I8: =IF($C8=0,"",OFFSET(INPUTS!I$5,$C8,0)) -> 0 | J8: =IF($C8=0,"",OFFSET(INPUTS!J$5,$C8,0)) -> 0 | K8: =IF($C8=0,"",OFFSET(INPUTS!K$5,$C8,0)) -> 12.333563 | ... Q8: =IF($C8=0,"",OFFSET(INPUTS!Q$5,$C8,0)) -> 100 | R8: =IF($C8=0,"",$P8-($J8*R$4)) -> 12.333563 | S8: =SUM(J8,R8) -> 12.333563 | T8: =IF(A8=0,"",A8) -> 7050I | U8: =IF(M8=0,"",M8) | V8: =IF(F8=0,"",F8&IF(OR(G8="",G8=0),"","+"&G8)) -> P4_C05 | W8: =IF(ISNUMBER(V8),COUNTIF($V$6:$V$17,V8),"") | X8: =$B8 -> EF21 | Z8: =IF($AK8>0,"",IF($R8="","",IF(AF8<0.2,10,IF(AF8<0.795,5,"")))) | AA8: =IF($AK8>0,"in Prepool",IF($R8="","",AF8*IF($Z8="",1,$Z8))) -> in Prepool | AB8: =IF(ISNUMBER(AA8),RANK(AA8,$AA$6:$AA$19,0),"") | AC8: =IF($AK8>0,"",IF($R8="","",R8*$AA8/IF($Z8="",1,$Z8))) | AD8: =IF($AK8>0,"",IF($R8="","",S8*$AA8/IF($Z8="",1,$Z8))) | AE8: =IF($AK8>0,"",IF($R8="","",D8*$AA8/IF($Z8="",1,$Z8))) | AF8: =IF(R8="","",$AA$4/R8*Q8) -> 0.81079572 | AG8: =IF(R8="","",Q8) -> 100 | AH8: =IF(R8="","",R8*AF8) -> 10 | AI8: =IF($AF8="","",AH8/$AH$20) -> 0.15151515 | AJ8: =IF($AF8="","",$AJ$2*AI8) -> 60.606061 | AK8: =IF(SUMIF('Prepool 1'!$X$6:$X$38,X8,'Prepool 1'!$AH$6:$AH$38)=1,1,IF(SUMIF('Prepool 1'!$X$6:$X$38,X8,'Prepool 1'!$AH$6:$AH$38)=0,IF(SUMIF('Prepool 2'!$X$6:$X$38,X8,'Prepool 2'!$AH$6:$AH$38)=1,2,IF(SUMIF('Prepool 2'!$X$6:$X$38,X8,'Prepool 2'!$AH$6:$AH$38)=0,,"ERR")),"ERR")) -> 2 | AM8: =AL8/$AL$20 -> 0 | AN8: =IF($AF8="","",AM8/AI8) -> 0 | AO8: =IF($AF8="","",AN8*R8) -> 0
A9: =IF(INPUTS!A9=0,"none",INPUTS!A9) -> 7050I | B9: =IF(INPUTS!B9=0,"none",INPUTS!B9) -> EF22 | C9: =IF(B9="none",0,MATCH(B9,INPUTS!$B$6:$B$69,0)) -> 4 | D9: =IF($C9=0,"",OFFSET(INPUTS!D$5,$C9,0)) -> 2.27232 | E9: =IF($C9=0,"",OFFSET(INPUTS!E$5,$C9,0)) -> 20 | F9: =IF($C9=0,"",OFFSET(INPUTS!F$5,$C9,0)) -> P4_D05 | G9: =IF($C9=0,"",OFFSET(INPUTS!G$5,$C9,0)) -> 0 | H9: =IF($C9=0,"",OFFSET(INPUTS!H$5,$C9,0)) -> 196 | I9: =IF($C9=0,"",OFFSET(INPUTS!I$5,$C9,0)) -> 0 | J9: =IF($C9=0,"",OFFSET(INPUTS!J$5,$C9,0)) -> 0 | K9: =IF($C9=0,"",OFFSET(INPUTS!K$5,$C9,0)) -> 17.565863 | ... Q9: =IF($C9=0,"",OFFSET(INPUTS!Q$5,$C9,0)) -> 10 | R9: =IF($C9=0,"",$P9-($J9*R$4)) -> 17.565863 | S9: =SUM(J9,R9) -> 17.565863 | T9: =IF(A9=0,"",A9) -> 7050I | U9: =IF(M9=0,"",M9) | V9: =IF(F9=0,"",F9&IF(OR(G9="",G9=0),"","+"&G9)) -> P4_D05 | W9: =IF(ISNUMBER(V9),COUNTIF($V$6:$V$17,V9),"") | X9: =$B9 -> EF22 | Z9: =IF($AK9>0,"",IF($R9="","",IF(AF9<0.2,10,IF(AF9<0.795,5,"")))) | AA9: =IF($AK9>0,"in Prepool",IF($R9="","",AF9*IF($Z9="",1,$Z9))) -> in Prepool | AB9: =IF(ISNUMBER(AA9),RANK(AA9,$AA$6:$AA$19,0),"") | AC9: =IF($AK9>0,"",IF($R9="","",R9*$AA9/IF($Z9="",1,$Z9))) | AD9: =IF($AK9>0,"",IF($R9="","",S9*$AA9/IF($Z9="",1,$Z9))) | AE9: =IF($AK9>0,"",IF($R9="","",D9*$AA9/IF($Z9="",1,$Z9))) | AF9: =IF(R9="","",$AA$4/R9*Q9) -> 0.056928602 | AG9: =IF(R9="","",Q9) -> 10 | AH9: =IF(R9="","",R9*AF9) -> 1 | AI9: =IF($AF9="","",AH9/$AH$20) -> 0.015151515 | AJ9: =IF($AF9="","",$AJ$2*AI9) -> 6.0606061 | AK9: =IF(SUMIF('Prepool 1'!$X$6:$X$38,X9,'Prepool 1'!$AH$6:$AH$38)=1,1,IF(SUMIF('Prepool 1'!$X$6:$X$38,X9,'Prepool 1'!$AH$6:$AH$38)=0,IF(SUMIF('Prepool 2'!$X$6:$X$38,X9,'Prepool 2'!$AH$6:$AH$38)=1,2,IF(SUMIF('Prepool 2'!$X$6:$X$38,X9,'Prepool 2'!$AH$6:$AH$38)=0,,"ERR")),"ERR")) -> 1 | AM9: =AL9/$AL$20 -> 0 | AN9: =IF($AF9="","",AM9/AI9) -> 0 | AO9: =IF($AF9="","",AN9*R9) -> 0
A10: =IF(INPUTS!A10=0,"none",INPUTS!A10) -> 7050I | B10: =IF(INPUTS!B10=0,"none",INPUTS!B10) -> EF23 | C10: =IF(B10="none",0,MATCH(B10,INPUTS!$B$6:$B$69,0)) -> 5 | D10: =IF($C10=0,"",OFFSET(INPUTS!D$5,$C10,0)) -> 2.45575 | E10: =IF($C10=0,"",OFFSET(INPUTS!E$5,$C10,0)) -> 20 | F10: =IF($C10=0,"",OFFSET(INPUTS!F$5,$C10,0)) -> P4_E05 | G10: =IF($C10=0,"",OFFSET(INPUTS!G$5,$C10,0)) -> 0 | H10: =IF($C10=0,"",OFFSET(INPUTS!H$5,$C10,0)) -> 198 | I10: =IF($C10=0,"",OFFSET(INPUTS!I$5,$C10,0)) -> 0 | J10: =IF($C10=0,"",OFFSET(INPUTS!J$5,$C10,0)) -> 0 | K10: =IF($C10=0,"",OFFSET(INPUTS!K$5,$C10,0)) -> 18.792088 | ... Q10: =IF($C10=0,"",OFFSET(INPUTS!Q$5,$C10,0)) -> 100 | R10: =IF($C10=0,"",$P10-($J10*R$4)) -> 18.792088 | S10: =SUM(J10,R10) -> 18.792088 | T10: =IF(A10=0,"",A10) -> 7050I | U10: =IF(M10=0,"",M10) | V10: =IF(F10=0,"",F10&IF(OR(G10="",G10=0),"","+"&G10)) -> P4_E05 | W10: =IF(ISNUMBER(V10),COUNTIF($V$6:$V$17,V10),"") | X10: =$B10 -> EF23 | Z10: =IF($AK10>0,"",IF($R10="","",IF(AF10<0.2,10,IF(AF10<0.795,5,"")))) | AA10: =IF($AK10>0,"in Prepool",IF($R10="","",AF10*IF($Z10="",1,$Z10))) -> in Prepool | AB10: =IF(ISNUMBER(AA10),RANK(AA10,$AA$6:$AA$19,0),"") | AC10: =IF($AK10>0,"",IF($R10="","",R10*$AA10/IF($Z10="",1,$Z10))) | AD10: =IF($AK10>0,"",IF($R10="","",S10*$AA10/IF($Z10="",1,$Z10))) | AE10: =IF($AK10>0,"",IF($R10="","",D10*$AA10/IF($Z10="",1,$Z10))) | AF10: =IF(R10="","",$AA$4/R10*Q10) -> 0.53213886 | AG10: =IF(R10="","",Q10) -> 100 | AH10: =IF(R10="","",R10*AF10) -> 10 | AI10: =IF($AF10="","",AH10/$AH$20) -> 0.15151515 | AJ10: =IF($AF10="","",$AJ$2*AI10) -> 60.606061 | AK10: =IF(SUMIF('Prepool 1'!$X$6:$X$38,X10,'Prepool 1'!$AH$6:$AH$38)=1,1,IF(SUMIF('Prepool 1'!$X$6:$X$38,X10,'Prepool 1'!$AH$6:$AH$38)=0,IF(SUMIF('Prepool 2'!$X$6:$X$38,X10,'Prepool 2'!$AH$6:$AH$38)=1,2,IF(SUMIF('Prepool 2'!$X$6:$X$38,X10,'Prepool 2'!$AH$6:$AH$38)=0,,"ERR")),"ERR")) -> 2 | AM10: =AL10/$AL$20 -> 0 | AN10: =IF($AF10="","",AM10/AI10) -> 0 | AO10: =IF($AF10="","",AN10*R10) -> 0
A11: =IF(INPUTS!A11=0,"none",INPUTS!A11) -> 7050I | B11: =IF(INPUTS!B11=0,"none",INPUTS!B11) -> EF24 | C11: =IF(B11="none",0,MATCH(B11,INPUTS!$B$6:$B$69,0)) -> 6 | D11: =IF($C11=0,"",OFFSET(INPUTS!D$5,$C11,0)) -> 2.39632 | E11: =IF($C11=0,"",OFFSET(INPUTS!E$5,$C11,0)) -> 20 | F11: =IF($C11=0,"",OFFSET(INPUTS!F$5,$C11,0)) -> P4_F05 | G11: =IF($C11=0,"",OFFSET(INPUTS!G$5,$C11,0)) -> 0 | H11: =IF($C11=0,"",OFFSET(INPUTS!H$5,$C11,0)) -> 198 | I11: =IF($C11=0,"",OFFSET(INPUTS!I$5,$C11,0)) -> 0 | J11: =IF($C11=0,"",OFFSET(INPUTS!J$5,$C11,0)) -> 0 | K11: =IF($C11=0,"",OFFSET(INPUTS!K$5,$C11,0)) -> 18.337313 | ... Q11: =IF($C11=0,"",OFFSET(INPUTS!Q$5,$C11,0)) -> 10 | R11: =IF($C11=0,"",$P11-($J11*R$4)) -> 18.337313 | S11: =SUM(J11,R11) -> 18.337313 | T11: =IF(A11=0,"",A11) -> 7050I | U11: =IF(M11=0,"",M11) | V11: =IF(F11=0,"",F11&IF(OR(G11="",G11=0),"","+"&G11)) -> P4_F05 | W11: =IF(ISNUMBER(V11),COUNTIF($V$6:$V$17,V11),"") | X11: =$B11 -> EF24 | Z11: =IF($AK11>0,"",IF($R11="","",IF(AF11<0.2,10,IF(AF11<0.795,5,"")))) | AA11: =IF($AK11>0,"in Prepool",IF($R11="","",AF11*IF($Z11="",1,$Z11))) -> in Prepool | AB11: =IF(ISNUMBER(AA11),RANK(AA11,$AA$6:$AA$19,0),"") | AC11: =IF($AK11>0,"",IF($R11="","",R11*$AA11/IF($Z11="",1,$Z11))) | AD11: =IF($AK11>0,"",IF($R11="","",S11*$AA11/IF($Z11="",1,$Z11))) | AE11: =IF($AK11>0,"",IF($R11="","",D11*$AA11/IF($Z11="",1,$Z11))) | AF11: =IF(R11="","",$AA$4/R11*Q11) -> 0.054533618 | AG11: =IF(R11="","",Q11) -> 10 | AH11: =IF(R11="","",R11*AF11) -> 1 | AI11: =IF($AF11="","",AH11/$AH$20) -> 0.015151515 | AJ11: =IF($AF11="","",$AJ$2*AI11) -> 6.0606061 | AK11: =IF(SUMIF('Prepool 1'!$X$6:$X$38,X11,'Prepool 1'!$AH$6:$AH$38)=1,1,IF(SUMIF('Prepool 1'!$X$6:$X$38,X11,'Prepool 1'!$AH$6:$AH$38)=0,IF(SUMIF('Prepool 2'!$X$6:$X$38,X11,'Prepool 2'!$AH$6:$AH$38)=1,2,IF(SUMIF('Prepool 2'!$X$6:$X$38,X11,'Prepool 2'!$AH$6:$AH$38)=0,,"ERR")),"ERR")) -> 1 | AM11: =AL11/$AL$20 -> 0 | AN11: =IF($AF11="","",AM11/AI11) -> 0 | AO11: =IF($AF11="","",AN11*R11) -> 0
A12: =IF(INPUTS!A12=0,"none",INPUTS!A12) -> 7050I | B12: =IF(INPUTS!B12=0,"none",INPUTS!B12) -> EF25 | C12: =IF(B12="none",0,MATCH(B12,INPUTS!$B$6:$B$69,0)) -> 7 | D12: =IF($C12=0,"",OFFSET(INPUTS!D$5,$C12,0)) -> 2.53 | E12: =IF($C12=0,"",OFFSET(INPUTS!E$5,$C12,0)) -> 20 | F12: =IF($C12=0,"",OFFSET(INPUTS!F$5,$C12,0)) -> P4_A06 | G12: =IF($C12=0,"",OFFSET(INPUTS!G$5,$C12,0)) -> 0 | H12: =IF($C12=0,"",OFFSET(INPUTS!H$5,$C12,0)) -> 199 | I12: =IF($C12=0,"",OFFSET(INPUTS!I$5,$C12,0)) -> 0 | J12: =IF($C12=0,"",OFFSET(INPUTS!J$5,$C12,0)) -> 0 | K12: =IF($C12=0,"",OFFSET(INPUTS!K$5,$C12,0)) -> 19.262982 | ... Q12: =IF($C12=0,"",OFFSET(INPUTS!Q$5,$C12,0)) -> 100 | R12: =IF($C12=0,"",$P12-($J12*R$4)) -> 19.262982 | S12: =SUM(J12,R12) -> 19.262982 | T12: =IF(A12=0,"",A12) -> 7050I | U12: =IF(M12=0,"",M12) | V12: =IF(F12=0,"",F12&IF(OR(G12="",G12=0),"","+"&G12)) -> P4_A06 | W12: =IF(ISNUMBER(V12),COUNTIF($V$6:$V$17,V12),"") | X12: =$B12 -> EF25 | Z12: =IF($AK12>0,"",IF($R12="","",IF(AF12<0.2,10,IF(AF12<0.795,5,"")))) | AA12: =IF($AK12>0,"in Prepool",IF($R12="","",AF12*IF($Z12="",1,$Z12))) -> in Prepool | AB12: =IF(ISNUMBER(AA12),RANK(AA12,$AA$6:$AA$19,0),"") | AC12: =IF($AK12>0,"",IF($R12="","",R12*$AA12/IF($Z12="",1,$Z12))) | AD12: =IF($AK12>0,"",IF($R12="","",S12*$AA12/IF($Z12="",1,$Z12))) | AE12: =IF($AK12>0,"",IF($R12="","",D12*$AA12/IF($Z12="",1,$Z12))) | AF12: =IF(R12="","",$AA$4/R12*Q12) -> 0.51913043 | AG12: =IF(R12="","",Q12) -> 100 | AH12: =IF(R12="","",R12*AF12) -> 10 | AI12: =IF($AF12="","",AH12/$AH$20) -> 0.15151515 | AJ12: =IF($AF12="","",$AJ$2*AI12) -> 60.606061 | AK12: =IF(SUMIF('Prepool 1'!$X$6:$X$38,X12,'Prepool 1'!$AH$6:$AH$38)=1,1,IF(SUMIF('Prepool 1'!$X$6:$X$38,X12,'Prepool 1'!$AH$6:$AH$38)=0,IF(SUMIF('Prepool 2'!$X$6:$X$38,X12,'Prepool 2'!$AH$6:$AH$38)=1,2,IF(SUMIF('Prepool 2'!$X$6:$X$38,X12,'Prepool 2'!$AH$6:$AH$38)=0,,"ERR")),"ERR")) -> 2 | AM12: =AL12/$AL$20 -> 0 | AN12: =IF($AF12="","",AM12/AI12) -> 0 | AO12: =IF($AF12="","",AN12*R12) -> 0
A13: =IF(INPUTS!A13=0,"none",INPUTS!A13) -> 7050I | B13: =IF(INPUTS!B13=0,"none",INPUTS!B13) -> EF26 | C13: =IF(B13="none",0,MATCH(B13,INPUTS!$B$6:$B$69,0)) -> 8 | D13: =IF($C13=0,"",OFFSET(INPUTS!D$5,$C13,0)) -> 3.3 | E13: =IF($C13=0,"",OFFSET(INPUTS!E$5,$C13,0)) -> 20 | F13: =IF($C13=0,"",OFFSET(INPUTS!F$5,$C13,0)) -> P4_B06 | G13: =IF($C13=0,"",OFFSET(INPUTS!G$5,$C13,0)) -> 0 | H13: =IF($C13=0,"",OFFSET(INPUTS!H$5,$C13,0)) -> 198 | I13: =IF($C13=0,"",OFFSET(INPUTS!I$5,$C13,0)) -> 0 | J13: =IF($C13=0,"",OFFSET(INPUTS!J$5,$C13,0)) -> 0 | K13: =IF($C13=0,"",OFFSET(INPUTS!K$5,$C13,0)) -> 25.252525 | ... Q13: =IF($C13=0,"",OFFSET(INPUTS!Q$5,$C13,0)) -> 10 | R13: =IF($C13=0,"",$P13-($J13*R$4)) -> 25.252525 | S13: =SUM(J13,R13) -> 25.252525 | T13: =IF(A13=0,"",A13) -> 7050I | U13: =IF(M13=0,"",M13) | V13: =IF(F13=0,"",F13&IF(OR(G13="",G13=0),"","+"&G13)) -> P4_B06 | W13: =IF(ISNUMBER(V13),COUNTIF($V$6:$V$17,V13),"") | X13: =$B13 -> EF26 | Z13: =IF($AK13>0,"",IF($R13="","",IF(AF13<0.2,10,IF(AF13<0.795,5,"")))) | AA13: =IF($AK13>0,"in Prepool",IF($R13="","",AF13*IF($Z13="",1,$Z13))) -> in Prepool | AB13: =IF(ISNUMBER(AA13),RANK(AA13,$AA$6:$AA$19,0),"") | AC13: =IF($AK13>0,"",IF($R13="","",R13*$AA13/IF($Z13="",1,$Z13))) | AD13: =IF($AK13>0,"",IF($R13="","",S13*$AA13/IF($Z13="",1,$Z13))) | AE13: =IF($AK13>0,"",IF($R13="","",D13*$AA13/IF($Z13="",1,$Z13))) | AF13: =IF(R13="","",$AA$4/R13*Q13) -> 0.0396 | AG13: =IF(R13="","",Q13) -> 10 | AH13: =IF(R13="","",R13*AF13) -> 1 | AI13: =IF($AF13="","",AH13/$AH$20) -> 0.015151515 | AJ13: =IF($AF13="","",$AJ$2*AI13) -> 6.0606061 | AK13: =IF(SUMIF('Prepool 1'!$X$6:$X$38,X13,'Prepool 1'!$AH$6:$AH$38)=1,1,IF(SUMIF('Prepool 1'!$X$6:$X$38,X13,'Prepool 1'!$AH$6:$AH$38)=0,IF(SUMIF('Prepool 2'!$X$6:$X$38,X13,'Prepool 2'!$AH$6:$AH$38)=1,2,IF(SUMIF('Prepool 2'!$X$6:$X$38,X13,'Prepool 2'!$AH$6:$AH$38)=0,,"ERR")),"ERR")) -> 1 | AM13: =AL13/$AL$20 -> 0 | AN13: =IF($AF13="","",AM13/AI13) -> 0 | AO13: =IF($AF13="","",AN13*R13) -> 0
A14: =IF(INPUTS!A14=0,"none",INPUTS!A14) -> 7050I | B14: =IF(INPUTS!B14=0,"none",INPUTS!B14) -> EF27 | C14: =IF(B14="none",0,MATCH(B14,INPUTS!$B$6:$B$69,0)) -> 9 | D14: =IF($C14=0,"",OFFSET(INPUTS!D$5,$C14,0)) -> 3.1212 | E14: =IF($C14=0,"",OFFSET(INPUTS!E$5,$C14,0)) -> 20 | F14: =IF($C14=0,"",OFFSET(INPUTS!F$5,$C14,0)) -> P4_C06 | G14: =IF($C14=0,"",OFFSET(INPUTS!G$5,$C14,0)) -> 0 | H14: =IF($C14=0,"",OFFSET(INPUTS!H$5,$C14,0)) -> 197 | I14: =IF($C14=0,"",OFFSET(INPUTS!I$5,$C14,0)) -> 0 | J14: =IF($C14=0,"",OFFSET(INPUTS!J$5,$C14,0)) -> 0 | K14: =IF($C14=0,"",OFFSET(INPUTS!K$5,$C14,0)) -> 24.005538 | ... Q14: =IF($C14=0,"",OFFSET(INPUTS!Q$5,$C14,0)) -> 100 | R14: =IF($C14=0,"",$P14-($J14*R$4)) -> 24.005538 | S14: =SUM(J14,R14) -> 24.005538 | T14: =IF(A14=0,"",A14) -> 7050I | U14: =IF(M14=0,"",M14) | V14: =IF(F14=0,"",F14&IF(OR(G14="",G14=0),"","+"&G14)) -> P4_C06 | W14: =IF(ISNUMBER(V14),COUNTIF($V$6:$V$17,V14),"") | X14: =$B14 -> EF27 | Z14: =IF($AK14>0,"",IF($R14="","",IF(AF14<0.2,10,IF(AF14<0.795,5,"")))) | AA14: =IF($AK14>0,"in Prepool",IF($R14="","",AF14*IF($Z14="",1,$Z14))) -> in Prepool | AB14: =IF(ISNUMBER(AA14),RANK(AA14,$AA$6:$AA$19,0),"") | AC14: =IF($AK14>0,"",IF($R14="","",R14*$AA14/IF($Z14="",1,$Z14))) | AD14: =IF($AK14>0,"",IF($R14="","",S14*$AA14/IF($Z14="",1,$Z14))) | AE14: =IF($AK14>0,"",IF($R14="","",D14*$AA14/IF($Z14="",1,$Z14))) | AF14: =IF(R14="","",$AA$4/R14*Q14) -> 0.41657055 | AG14: =IF(R14="","",Q14) -> 100 | AH14: =IF(R14="","",R14*AF14) -> 10 | AI14: =IF($AF14="","",AH14/$AH$20) -> 0.15151515 | AJ14: =IF($AF14="","",$AJ$2*AI14) -> 60.606061 | AK14: =IF(SUMIF('Prepool 1'!$X$6:$X$38,X14,'Prepool 1'!$AH$6:$AH$38)=1,1,IF(SUMIF('Prepool 1'!$X$6:$X$38,X14,'Prepool 1'!$AH$6:$AH$38)=0,IF(SUMIF('Prepool 2'!$X$6:$X$38,X14,'Prepool 2'!$AH$6:$AH$38)=1,2,IF(SUMIF('Prepool 2'!$X$6:$X$38,X14,'Prepool 2'!$AH$6:$AH$38)=0,,"ERR")),"ERR")) -> 2 | AM14: =AL14/$AL$20 -> 0 | AN14: =IF($AF14="","",AM14/AI14) -> 0 | AO14: =IF($AF14="","",AN14*R14) -> 0
A15: =IF(INPUTS!A15=0,"none",INPUTS!A15) -> 7050I | B15: =IF(INPUTS!B15=0,"none",INPUTS!B15) -> EF28 | C15: =IF(B15="none",0,MATCH(B15,INPUTS!$B$6:$B$69,0)) -> 10 | D15: =IF($C15=0,"",OFFSET(INPUTS!D$5,$C15,0)) -> 0.1 | E15: =IF($C15=0,"",OFFSET(INPUTS!E$5,$C15,0)) -> 20 | F15: =IF($C15=0,"",OFFSET(INPUTS!F$5,$C15,0)) -> P4_D06 | G15: =IF($C15=0,"",OFFSET(INPUTS!G$5,$C15,0)) -> 0 | H15: =IF($C15=0,"",OFFSET(INPUTS!H$5,$C15,0)) -> 198 | I15: =IF($C15=0,"",OFFSET(INPUTS!I$5,$C15,0)) -> 0 | J15: =IF($C15=0,"",OFFSET(INPUTS!J$5,$C15,0)) -> 0 | K15: =IF($C15=0,"",OFFSET(INPUTS!K$5,$C15,0)) -> 0.76522804 | ... Q15: =IF($C15=0,"",OFFSET(INPUTS!Q$5,$C15,0)) -> 10 | R15: =IF($C15=0,"",$P15-($J15*R$4)) -> 0.76522804 | S15: =SUM(J15,R15) -> 0.76522804 | T15: =IF(A15=0,"",A15) -> 7050I | U15: =IF(M15=0,"",M15) | V15: =IF(F15=0,"",F15&IF(OR(G15="",G15=0),"","+"&G15)) -> P4_D06 | W15: =IF(ISNUMBER(V15),COUNTIF($V$6:$V$17,V15),"") | X15: =$B15 -> EF28 | Z15: =IF($AK15>0,"",IF($R15="","",IF(AF15<0.2,10,IF(AF15<0.795,5,"")))) | AA15: =IF($AK15>0,"in Prepool",IF($R15="","",AF15*IF($Z15="",1,$Z15))) -> in Prepool | AB15: =IF(ISNUMBER(AA15),RANK(AA15,$AA$6:$AA$19,0),"") | AC15: =IF($AK15>0,"",IF($R15="","",R15*$AA15/IF($Z15="",1,$Z15))) | AD15: =IF($AK15>0,"",IF($R15="","",S15*$AA15/IF($Z15="",1,$Z15))) | AE15: =IF($AK15>0,"",IF($R15="","",D15*$AA15/IF($Z15="",1,$Z15))) | AF15: =IF(R15="","",$AA$4/R15*Q15) -> 1.3068 | AG15: =IF(R15="","",Q15) -> 10 | AH15: =IF(R15="","",R15*AF15) -> 1 | AI15: =IF($AF15="","",AH15/$AH$20) -> 0.015151515 | AJ15: =IF($AF15="","",$AJ$2*AI15) -> 6.0606061 | AK15: =IF(SUMIF('Prepool 1'!$X$6:$X$38,X15,'Prepool 1'!$AH$6:$AH$38)=1,1,IF(SUMIF('Prepool 1'!$X$6:$X$38,X15,'Prepool 1'!$AH$6:$AH$38)=0,IF(SUMIF('Prepool 2'!$X$6:$X$38,X15,'Prepool 2'!$AH$6:$AH$38)=1,2,IF(SUMIF('Prepool 2'!$X$6:$X$38,X15,'Prepool 2'!$AH$6:$AH$38)=0,,"ERR")),"ERR")) -> 2 | AM15: =AL15/$AL$20 -> 0 | AN15: =IF($AF15="","",AM15/AI15) -> 0 | AO15: =IF($AF15="","",AN15*R15) -> 0
A16: =IF(INPUTS!A16=0,"none",INPUTS!A16) -> 7050I | B16: =IF(INPUTS!B16=0,"none",INPUTS!B16) -> EF29 | C16: =IF(B16="none",0,MATCH(B16,INPUTS!$B$6:$B$69,0)) -> 11 | D16: =IF($C16=0,"",OFFSET(INPUTS!D$5,$C16,0)) -> 0.1 | E16: =IF($C16=0,"",OFFSET(INPUTS!E$5,$C16,0)) -> 20 | F16: =IF($C16=0,"",OFFSET(INPUTS!F$5,$C16,0)) -> P4_E06 | G16: =IF($C16=0,"",OFFSET(INPUTS!G$5,$C16,0)) -> 0 | H16: =IF($C16=0,"",OFFSET(INPUTS!H$5,$C16,0)) -> 196 | I16: =IF($C16=0,"",OFFSET(INPUTS!I$5,$C16,0)) -> 0 | J16: =IF($C16=0,"",OFFSET(INPUTS!J$5,$C16,0)) -> 0 | K16: =IF($C16=0,"",OFFSET(INPUTS!K$5,$C16,0)) -> 0.77303649 | ... Q16: =IF($C16=0,"",OFFSET(INPUTS!Q$5,$C16,0)) -> 100 | R16: =IF($C16=0,"",$P16-($J16*R$4)) -> 0.77303649 | S16: =SUM(J16,R16) -> 0.77303649 | T16: =IF(A16=0,"",A16) -> 7050I | U16: =IF(M16=0,"",M16) | V16: =IF(F16=0,"",F16&IF(OR(G16="",G16=0),"","+"&G16)) -> P4_E06 | W16: =IF(ISNUMBER(V16),COUNTIF($V$6:$V$17,V16),"") | X16: =$B16 -> EF29 | Z16: =IF($AK16>0,"",IF($R16="","",IF(AF16<0.2,10,IF(AF16<0.795,5,"")))) | AA16: =IF($AK16>0,"in Prepool",IF($R16="","",AF16*IF($Z16="",1,$Z16))) -> 12.936 | AB16: =IF(ISNUMBER(AA16),RANK(AA16,$AA$6:$AA$19,0),"") -> 1 | AC16: =IF($AK16>0,"",IF($R16="","",R16*$AA16/IF($Z16="",1,$Z16))) -> 10 | AD16: =IF($AK16>0,"",IF($R16="","",S16*$AA16/IF($Z16="",1,$Z16))) -> 10 | AE16: =IF($AK16>0,"",IF($R16="","",D16*$AA16/IF($Z16="",1,$Z16))) -> 1.2936 | AF16: =IF(R16="","",$AA$4/R16*Q16) -> 12.936 | AG16: =IF(R16="","",Q16) -> 100 | AH16: =IF(R16="","",R16*AF16) -> 10 | AI16: =IF($AF16="","",AH16/$AH$20) -> 0.15151515 | AJ16: =IF($AF16="","",$AJ$2*AI16) -> 60.606061 | AK16: =IF(SUMIF('Prepool 1'!$X$6:$X$38,X16,'Prepool 1'!$AH$6:$AH$38)=1,1,IF(SUMIF('Prepool 1'!$X$6:$X$38,X16,'Prepool 1'!$AH$6:$AH$38)=0,IF(SUMIF('Prepool 2'!$X$6:$X$38,X16,'Prepool 2'!$AH$6:$AH$38)=1,2,IF(SUMIF('Prepool 2'!$X$6:$X$38,X16,'Prepool 2'!$AH$6:$AH$38)=0,,"ERR")),"ERR")) -> 0 | AM16: =AL16/$AL$20 -> 0 | AN16: =IF($AF16="","",AM16/AI16) -> 0 | AO16: =IF($AF16="","",AN16*R16) -> 0
A17: =IF(INPUTS!A17=0,"none",INPUTS!A17) -> 7050I | B17: =IF(INPUTS!B17=0,"none",INPUTS!B17) -> EF30 | C17: =IF(B17="none",0,MATCH(B17,INPUTS!$B$6:$B$69,0)) -> 12 | D17: =IF($C17=0,"",OFFSET(INPUTS!D$5,$C17,0)) -> 0.1 | E17: =IF($C17=0,"",OFFSET(INPUTS!E$5,$C17,0)) -> 20 | F17: =IF($C17=0,"",OFFSET(INPUTS!F$5,$C17,0)) -> P4_F06 | G17: =IF($C17=0,"",OFFSET(INPUTS!G$5,$C17,0)) -> 0 | H17: =IF($C17=0,"",OFFSET(INPUTS!H$5,$C17,0)) -> 197 | I17: =IF($C17=0,"",OFFSET(INPUTS!I$5,$C17,0)) -> 0 | J17: =IF($C17=0,"",OFFSET(INPUTS!J$5,$C17,0)) -> 0 | K17: =IF($C17=0,"",OFFSET(INPUTS!K$5,$C17,0)) -> 0.76911244 | ... Q17: =IF($C17=0,"",OFFSET(INPUTS!Q$5,$C17,0)) -> 10 | R17: =IF($C17=0,"",$P17-($J17*R$4)) -> 0.76911244 | S17: =SUM(J17,R17) -> 0.76911244 | T17: =IF(A17=0,"",A17) -> 7050I | U17: =IF(M17=0,"",M17) | V17: =IF(F17=0,"",F17&IF(OR(G17="",G17=0),"","+"&G17)) -> P4_F06 | W17: =IF(ISNUMBER(V17),COUNTIF($V$6:$V$17,V17),"") | X17: =$B17 -> EF30 | Z17: =IF($AK17>0,"",IF($R17="","",IF(AF17<0.2,10,IF(AF17<0.795,5,"")))) | AA17: =IF($AK17>0,"in Prepool",IF($R17="","",AF17*IF($Z17="",1,$Z17))) -> in Prepool | AB17: =IF(ISNUMBER(AA17),RANK(AA17,$AA$6:$AA$19,0),"") | AC17: =IF($AK17>0,"",IF($R17="","",R17*$AA17/IF($Z17="",1,$Z17))) | AD17: =IF($AK17>0,"",IF($R17="","",S17*$AA17/IF($Z17="",1,$Z17))) | AE17: =IF($AK17>0,"",IF($R17="","",D17*$AA17/IF($Z17="",1,$Z17))) | AF17: =IF(R17="","",$AA$4/R17*Q17) -> 1.3002 | AG17: =IF(R17="","",Q17) -> 10 | AH17: =IF(R17="","",R17*AF17) -> 1 | AI17: =IF($AF17="","",AH17/$AH$20) -> 0.015151515 | AJ17: =IF($AF17="","",$AJ$2*AI17) -> 6.0606061 | AK17: =IF(SUMIF('Prepool 1'!$X$6:$X$38,X17,'Prepool 1'!$AH$6:$AH$38)=1,1,IF(SUMIF('Prepool 1'!$X$6:$X$38,X17,'Prepool 1'!$AH$6:$AH$38)=0,IF(SUMIF('Prepool 2'!$X$6:$X$38,X17,'Prepool 2'!$AH$6:$AH$38)=1,2,IF(SUMIF('Prepool 2'!$X$6:$X$38,X17,'Prepool 2'!$AH$6:$AH$38)=0,,"ERR")),"ERR")) -> 2 | AM17: =AL17/$AL$20 -> 0 | AN17: =IF($AF17="","",AM17/AI17) -> 0 | AO17: =IF($AF17="","",AN17*R17) -> 0
B18: Prepool 1 | D18: ='Prepool 1'!$AA$46 -> 2.2892019 | E18: ='Prepool 1'!$AA$43 -> 6.8329489 | R18: ='Prepool 1'!$AA$44 -> 17.561964 | S18: ='Prepool 1'!$AA$44 -> 17.561964 | V18: Mix | X18: =$B18 -> Prepool 1 | Y18: ='Prepool 1'!$AA$47&" libs" -> 4 libs | Z18: =IF(AF18<0.2,10,IF(AF18<0.795,5,"")) -> 5 | AA18: =IF(OR(R18="",AK$3="no"),"",AF18*IF($Z18="",1,$Z18)) -> 1.1388248 | AB18: =IF(ISNUMBER(AA18),RANK(AA18,$AA$6:$AA$19,0),"") -> 3 | AC18: =IF(OR(R18="",AK$3="no"),"",R18*$AA18/IF($Z18="",1,$Z18)) -> 4 | AD18: =IF(OR(R18="",AK$3="no"),"",S18*$AA18/IF($Z18="",1,$Z18)) -> 4 | AE18: =IF(OR(R18="",AK$3="no"),"",D18*$AA18/IF($Z18="",1,$Z18)) -> 0.5214 | AF18: =IF(OR(R18="",AK$3="no"),"",$AA$4/R18*AG18) -> 0.22776496 | AG18: =SUM('Prepool 1'!$AG$5:$AG$39) -> 40 | AH18: =IF(OR(R18="",AK$3="no"),"",R18*AF18) -> 4 | AK18: 1
B19: Prepool 2 | D19: ='Prepool 2'!$AA$46 -> 1.2087637 | E19: ='Prepool 2'!$AA$43 -> 22.484791 | R19: ='Prepool 2'!$AA$44 -> 9.2506973 | S19: ='Prepool 2'!$AA$44 -> 9.2506973 | V19: Mix | X19: =$B19 -> Prepool 2 | Y19: ='Prepool 2'!$AA$47&" libs" -> 7 libs | Z19: =IF(AF19<0.2,10,IF(AF19<0.795,5,"")) | AA19: =IF(OR(R19="",AK$3="no"),"",AF19*IF($Z19="",1,$Z19)) -> 5.6211979 | AB19: =IF(ISNUMBER(AA19),RANK(AA19,$AA$6:$AA$19,0),"") -> 2 | AC19: =IF(OR(R19="",AK$3="no"),"",R19*$AA19/IF($Z19="",1,$Z19)) -> 52 | AD19: =IF(OR(R19="",AK$3="no"),"",S19*$AA19/IF($Z19="",1,$Z19)) -> 52 | AE19: =IF(OR(R19="",AK$3="no"),"",D19*$AA19/IF($Z19="",1,$Z19)) -> 6.7947 | AF19: =IF(OR(R19="",AK$3="no"),"",$AA$4/R19*AG19) -> 5.6211979 | AG19: =SUM('Prepool 2'!$AG$5:$AG$39) -> 520 | AH19: =IF(OR(R19="",AK$3="no"),"",R19*AF19) -> 52 | AK19: 2
H20: =IF(COUNT(H6:H17)=0,0,AVERAGE(H6:H17)) -> 197.58333 | I20: avg peak | AA20: =SUM(AA6:AA19) -> 19.696023 | AC20: =SUM(AC6:AC19) -> 66 | AD20: =SUM(AD6:AD19) -> 66 | AE20: =SUM(AE6:AE19) -> 8.6097 | AG20: =SUM(AG6:AG17) -> 660 | AH20: =SUM(AH6:AH17) -> 66 | AI20: =SUM(AI6:AI17) -> 1 | AJ20: =SUM(AJ6:AJ17) -> 400 | AK20: =SUM(AK6:AK17) -> 18 | AL20: =MAX(1,SUM(AL6:AL17)) -> 1
J21: =SUMPRODUCT(J$6:J$17,$AF$6:$AF$17) -> 0 | K21: =SUMPRODUCT(K$6:K$17,$AF$6:$AF$17) -> 66 | P21: =SUMPRODUCT(P$6:P$17,$AF$6:$AF$17) -> 66 | Q21: total pmol | T21: Smear analysis based on: 185-210bp target size
I22: %AdDimer | J22: =IF(J21=0,0,J21/K21) -> 0 | Z22: Lib vol | AA22: =SUM(AA6:AA19) -> 19.696023 | AB22: ul
Z23: 0.1x TE buffer | AA23: =AC23 -> 0 | AB23: ul | AC23: 0 | AD23: add TE
Z24: Pool vol | AA24: =SUM(AA22:AA23) -> 19.696023 | AB24: ul tot vol
AA25: =IF($AA$22=0,"",AC20/$AA$24) -> 3.3509303 | AB25: adj lib nM
Z26: post-size selection estimate | AA26: =IF($AA$22=0,"",AD20/$AA$24) -> 3.3509303 | AB26: total nM
AA27: =IF($AA$22=0,"",AE20/$AA$24) -> 0.43712886 | AB27: total ng/ul | AE27: =IF(AA24=0,"",AA27*AA24) -> 8.6097 | AF27: total ng
Z28: # libraries | AA28: =COUNTIF(AJ6:AJ17,">0") -> 12
X30: Needs final bead clean? | AA30: yes
T31: reduce free primers before Pippin | AA31: 2 | AB31: x ratio
Z32: add beads | AA32: =AA24*AA31 -> 39.392045 | AB32: ul beads
Z33: final elution vol | AA33: 44 | AB33: ul
Z34: final Qubit | AB34: ng/ul
Z35: expected Qubit (no loss) | AA35: =IF(AA33=0,"",AA24/AA33*AA27) -> 0.195675 | AB35: ng/ul
Z36: est nM (no loss) | AA36: =IF(AA33=0,"",AA24/AA33*AA26) -> 1.5 | AB36: nM
X38: Pippin: | AA38: 20 | AB38: ul of final BC pool (=half)
AB39: 3% gel
T41: filter on Project <> none

Sheet Prepool 1
T1: Prepool 1
A2: Don’t add libraries here -- only add on INPUTS sheet! Filter this sheet for printing (no need to delete rows) | T2: ='Final Pool'!$T$2 -> 45982 | Z2: =COUNT(Z6:Z39) -> 0 | AA2: =COUNTIF(AA6:AA39,">2") -> 2 | AH2: Select Libs Here
D3: Final Library | O3: =INPUTS!O3 -> Empirical | P3: =INPUTS!P3 -> Use | R3: AdDimer adjust | X3: Final Lib | AA3: Pool | AH3: include | AI3: included
B4: Lib | D4: =INPUTS!D4 -> Final | E4: =INPUTS!E4 -> Total | I4: =INPUTS!I4 -> lowMW=primer | J4: =INPUTS!J4 -> AdDimer | K4: =INPUTS!K4 -> Library | L4: =INPUTS!L4 -> Total | O4: =INPUTS!O4 -> Library | P4: =INPUTS!P4 -> Library | Q4: Final pool | R4: 0.05 | V4: =COUNTIF(W6:W38,">1") -> 0 | Z4: pre-dil | AA4: 3 | AG4: target | AH4: in this | AI4: in
A5: Project ID | B5: Name | C5: match | D5: =INPUTS!D5 -> ng/ul | E5: =INPUTS!E5 -> vol | F5: =INPUTS!F5 -> UDI: Plate_Well | G5: =INPUTS!G5 -> notes | H5: =INPUTS!H5 -> Adj peak size | I5: =INPUTS!I5 -> %ofLib | J5: =INPUTS!J5 -> nM | K5: =INPUTS!K5 -> nM | ... Q5: =INPUTS!Q5 -> Reads (M) | R5: Adj lib nM | S5: tot nM | T5: Project# | U5: Lib# | V5: BC | X5: name | Y5: Loc | AA5: vol | AC5: adj lib pmol | AD5: tot pmol | AE5: total ng | AF5: stock vol | AG5: M reads | AH5: Prepool | AI5: Prepool 2
A6: =IF(INPUTS!A6=0,"none",INPUTS!A6) -> 7050I | B6: =IF(INPUTS!B6=0,"none",INPUTS!B6) -> EF19 | C6: =IF(B6="none",0,MATCH(B6,INPUTS!$B$6:$B$69,0)) -> 1 | D6: =IF($C6=0,"",OFFSET(INPUTS!D$5,$C6,0)) -> 1.7766 | E6: =IF($C6=0,"",OFFSET(INPUTS!E$5,$C6,0)) -> 20 | F6: =IF($C6=0,"",OFFSET(INPUTS!F$5,$C6,0)) -> P4_A05 | G6: =IF($C6=0,"",OFFSET(INPUTS!G$5,$C6,0)) -> 0 | H6: =IF($C6=0,"",OFFSET(INPUTS!H$5,$C6,0)) -> 198 | I6: =IF($C6=0,"",OFFSET(INPUTS!I$5,$C6,0)) -> 0 | J6: =IF($C6=0,"",OFFSET(INPUTS!J$5,$C6,0)) -> 0 | K6: =IF($C6=0,"",OFFSET(INPUTS!K$5,$C6,0)) -> 13.595041 | ... Q6: =IF($C6=0,"",OFFSET(INPUTS!Q$5,$C6,0)) -> 100 | R6: =IF($C6=0,"",$P6-($J6*R$4)) -> 13.595041 | S6: =SUM(J6,R6) -> 13.595041 | T6: =IF(A6=0,"",A6) -> 7050I | U6: =IF(M6=0,"",M6) | V6: =IF(F6=0,"",F6&IF(OR(G6="",G6=0),"","+"&G6)) -> P4_A05 | W6: =IF(ISNUMBER(V6),COUNTIF($V$6:$V$38,V6),"") | X6: =$B6 -> EF19 | Y6: =IF(N6=0,"",N6) | Z6: =IF($AH6=0,"",IF($R6="","",IF(AF6<0.2,10,IF(AF6<0.795,5,"")))) | AA6: =IF($AH6=0,"",IF($R6="","",AF6*IF($Z6="",1,$Z6))) | AB6: =IF(ISNUMBER(AA6),RANK(AA6,$AA$6:$AA$38,0),"") | AC6: =IF($AH6=0,"",IF($R6="","",R6*$AA6/IF($Z6="",1,$Z6))) | AD6: =IF($AH6=0,"",IF($R6="","",S6*$AA6/IF($Z6="",1,$Z6))) | AE6: =IF($AH6=0,"",IF($R6="","",D6*$AA6/IF($Z6="",1,$Z6))) | AF6: =IF(R6="","",$AA$4/R6*Q6) -> 22.066869 | AG6: =IF($AH6=0,"",Q6) | AH6: 0 | AI6: =IF(C$6=0,0,SUMIF('Prepool 2'!$X$5:$X$38,X6,'Prepool 2'!$AH$5:$AH$38)*2) -> 2
A7: =IF(INPUTS!A7=0,"none",INPUTS!A7) -> 7050I | B7: =IF(INPUTS!B7=0,"none",INPUTS!B7) -> EF20 | C7: =IF(B7="none",0,MATCH(B7,INPUTS!$B$6:$B$69,0)) -> 2 | D7: =IF($C7=0,"",OFFSET(INPUTS!D$5,$C7,0)) -> 1.70372 | E7: =IF($C7=0,"",OFFSET(INPUTS!E$5,$C7,0)) -> 20 | F7: =IF($C7=0,"",OFFSET(INPUTS!F$5,$C7,0)) -> P4_B05 | G7: =IF($C7=0,"",OFFSET(INPUTS!G$5,$C7,0)) -> 0 | H7: =IF($C7=0,"",OFFSET(INPUTS!H$5,$C7,0)) -> 198 | I7: =IF($C7=0,"",OFFSET(INPUTS!I$5,$C7,0)) -> 0 | J7: =IF($C7=0,"",OFFSET(INPUTS!J$5,$C7,0)) -> 0 | K7: =IF($C7=0,"",OFFSET(INPUTS!K$5,$C7,0)) -> 13.037343 | ... Q7: =IF($C7=0,"",OFFSET(INPUTS!Q$5,$C7,0)) -> 10 | R7: =IF($C7=0,"",$P7-($J7*R$4)) -> 13.037343 | S7: =SUM(J7,R7) -> 13.037343 | T7: =IF(A7=0,"",A7) -> 7050I | U7: =IF(M7=0,"",M7) | V7: =IF(F7=0,"",F7&IF(OR(G7="",G7=0),"","+"&G7)) -> P4_B05 | W7: =IF(ISNUMBER(V7),COUNTIF($V$6:$V$38,V7),"") | X7: =$B7 -> EF20 | Y7: =IF(N7=0,"",N7) | Z7: =IF($AH7=0,"",IF($R7="","",IF(AF7<0.2,10,IF(AF7<0.795,5,"")))) | AA7: =IF($AH7=0,"",IF($R7="","",AF7*IF($Z7="",1,$Z7))) -> 2.3010823 | AB7: =IF(ISNUMBER(AA7),RANK(AA7,$AA$6:$AA$38,0),"") -> 1 | AC7: =IF($AH7=0,"",IF($R7="","",R7*$AA7/IF($Z7="",1,$Z7))) -> 30 | AD7: =IF($AH7=0,"",IF($R7="","",S7*$AA7/IF($Z7="",1,$Z7))) -> 30 | AE7: =IF($AH7=0,"",IF($R7="","",D7*$AA7/IF($Z7="",1,$Z7))) -> 3.9204 | AF7: =IF(R7="","",$AA$4/R7*Q7) -> 2.3010823 | AG7: =IF($AH7=0,"",Q7) -> 10 | AH7: 1 | AI7: =IF(C$6=0,0,SUMIF('Prepool 2'!$X$5:$X$38,X7,'Prepool 2'!$AH$5:$AH$38)*2) -> 0
A8: =IF(INPUTS!A8=0,"none",INPUTS!A8) -> 7050I | B8: =IF(INPUTS!B8=0,"none",INPUTS!B8) -> EF21 | C8: =IF(B8="none",0,MATCH(B8,INPUTS!$B$6:$B$69,0)) -> 3 | D8: =IF($C8=0,"",OFFSET(INPUTS!D$5,$C8,0)) -> 1.61175 | E8: =IF($C8=0,"",OFFSET(INPUTS!E$5,$C8,0)) -> 20 | F8: =IF($C8=0,"",OFFSET(INPUTS!F$5,$C8,0)) -> P4_C05 | G8: =IF($C8=0,"",OFFSET(INPUTS!G$5,$C8,0)) -> 0 | H8: =IF($C8=0,"",OFFSET(INPUTS!H$5,$C8,0)) -> 198 | I8: =IF($C8=0,"",OFFSET(INPUTS!I$5,$C8,0)) -> 0 | J8: =IF($C8=0,"",OFFSET(INPUTS!J$5,$C8,0)) -> 0 | K8: =IF($C8=0,"",OFFSET(INPUTS!K$5,$C8,0)) -> 12.333563 | ... Q8: =IF($C8=0,"",OFFSET(INPUTS!Q$5,$C8,0)) -> 100 | R8: =IF($C8=0,"",$P8-($J8*R$4)) -> 12.333563 | S8: =SUM(J8,R8) -> 12.333563 | T8: =IF(A8=0,"",A8) -> 7050I | U8: =IF(M8=0,"",M8) | V8: =IF(F8=0,"",F8&IF(OR(G8="",G8=0),"","+"&G8)) -> P4_C05 | W8: =IF(ISNUMBER(V8),COUNTIF($V$6:$V$38,V8),"") | X8: =$B8 -> EF21 | Y8: =IF(N8=0,"",N8) | Z8: =IF($AH8=0,"",IF($R8="","",IF(AF8<0.2,10,IF(AF8<0.795,5,"")))) | AA8: =IF($AH8=0,"",IF($R8="","",AF8*IF($Z8="",1,$Z8))) | AB8: =IF(ISNUMBER(AA8),RANK(AA8,$AA$6:$AA$38,0),"") | AC8: =IF($AH8=0,"",IF($R8="","",R8*$AA8/IF($Z8="",1,$Z8))) | AD8: =IF($AH8=0,"",IF($R8="","",S8*$AA8/IF($Z8="",1,$Z8))) | AE8: =IF($AH8=0,"",IF($R8="","",D8*$AA8/IF($Z8="",1,$Z8))) | AF8: =IF(R8="","",$AA$4/R8*Q8) -> 24.323872 | AG8: =IF($AH8=0,"",Q8) | AH8: 0 | AI8: =IF(C$6=0,0,SUMIF('Prepool 2'!$X$5:$X$38,X8,'Prepool 2'!$AH$5:$AH$38)*2) -> 2
A9: =IF(INPUTS!A9=0,"none",INPUTS!A9) -> 7050I | B9: =IF(INPUTS!B9=0,"none",INPUTS!B9) -> EF22 | C9: =IF(B9="none",0,MATCH(B9,INPUTS!$B$6:$B$69,0)) -> 4 | D9: =IF($C9=0,"",OFFSET(INPUTS!D$5,$C9,0)) -> 2.27232 | E9: =IF($C9=0,"",OFFSET(INPUTS!E$5,$C9,0)) -> 20 | F9: =IF($C9=0,"",OFFSET(INPUTS!F$5,$C9,0)) -> P4_D05 | G9: =IF($C9=0,"",OFFSET(INPUTS!G$5,$C9,0)) -> 0 | H9: =IF($C9=0,"",OFFSET(INPUTS!H$5,$C9,0)) -> 196 | I9: =IF($C9=0,"",OFFSET(INPUTS!I$5,$C9,0)) -> 0 | J9: =IF($C9=0,"",OFFSET(INPUTS!J$5,$C9,0)) -> 0 | K9: =IF($C9=0,"",OFFSET(INPUTS!K$5,$C9,0)) -> 17.565863 | ... Q9: =IF($C9=0,"",OFFSET(INPUTS!Q$5,$C9,0)) -> 10 | R9: =IF($C9=0,"",$P9-($J9*R$4)) -> 17.565863 | S9: =SUM(J9,R9) -> 17.565863 | T9: =IF(A9=0,"",A9) -> 7050I | U9: =IF(M9=0,"",M9) | V9: =IF(F9=0,"",F9&IF(OR(G9="",G9=0),"","+"&G9)) -> P4_D05 | W9: =IF(ISNUMBER(V9),COUNTIF($V$6:$V$38,V9),"") | X9: =$B9 -> EF22 | Y9: =IF(N9=0,"",N9) | Z9: =IF($AH9=0,"",IF($R9="","",IF(AF9<0.2,10,IF(AF9<0.795,5,"")))) | AA9: =IF($AH9=0,"",IF($R9="","",AF9*IF($Z9="",1,$Z9))) -> 1.707858 | AB9: =IF(ISNUMBER(AA9),RANK(AA9,$AA$6:$AA$38,0),"") -> 2 | AC9: =IF($AH9=0,"",IF($R9="","",R9*$AA9/IF($Z9="",1,$Z9))) -> 30 | AD9: =IF($AH9=0,"",IF($R9="","",S9*$AA9/IF($Z9="",1,$Z9))) -> 30 | AE9: =IF($AH9=0,"",IF($R9="","",D9*$AA9/IF($Z9="",1,$Z9))) -> 3.8808 | AF9: =IF(R9="","",$AA$4/R9*Q9) -> 1.707858 | AG9: =IF($AH9=0,"",Q9) -> 10 | AH9: 1 | AI9: =IF(C$6=0,0,SUMIF('Prepool 2'!$X$5:$X$38,X9,'Prepool 2'!$AH$5:$AH$38)*2) -> 0
A10: =IF(INPUTS!A10=0,"none",INPUTS!A10) -> 7050I | B10: =IF(INPUTS!B10=0,"none",INPUTS!B10) -> EF23 | C10: =IF(B10="none",0,MATCH(B10,INPUTS!$B$6:$B$69,0)) -> 5 | D10: =IF($C10=0,"",OFFSET(INPUTS!D$5,$C10,0)) -> 2.45575 | E10: =IF($C10=0,"",OFFSET(INPUTS!E$5,$C10,0)) -> 20 | F10: =IF($C10=0,"",OFFSET(INPUTS!F$5,$C10,0)) -> P4_E05 | G10: =IF($C10=0,"",OFFSET(INPUTS!G$5,$C10,0)) -> 0 | H10: =IF($C10=0,"",OFFSET(INPUTS!H$5,$C10,0)) -> 198 | I10: =IF($C10=0,"",OFFSET(INPUTS!I$5,$C10,0)) -> 0 | J10: =IF($C10=0,"",OFFSET(INPUTS!J$5,$C10,0)) -> 0 | K10: =IF($C10=0,"",OFFSET(INPUTS!K$5,$C10,0)) -> 18.792088 | ... Q10: =IF($C10=0,"",OFFSET(INPUTS!Q$5,$C10,0)) -> 100 | R10: =IF($C10=0,"",$P10-($J10*R$4)) -> 18.792088 | S10: =SUM(J10,R10) -> 18.792088 | T10: =IF(A10=0,"",A10) -> 7050I | U10: =IF(M10=0,"",M10) | V10: =IF(F10=0,"",F10&IF(OR(G10="",G10=0),"","+"&G10)) -> P4_E05 | W10: =IF(ISNUMBER(V10),COUNTIF($V$6:$V$38,V10),"") | X10: =$B10 -> EF23 | Y10: =IF(N10=0,"",N10) | Z10: =IF($AH10=0,"",IF($R10="","",IF(AF10<0.2,10,IF(AF10<0.795,5,"")))) | AA10: =IF($AH10=0,"",IF($R10="","",AF10*IF($Z10="",1,$Z10))) | AB10: =IF(ISNUMBER(AA10),RANK(AA10,$AA$6:$AA$38,0),"") | AC10: =IF($AH10=0,"",IF($R10="","",R10*$AA10/IF($Z10="",1,$Z10))) | AD10: =IF($AH10=0,"",IF($R10="","",S10*$AA10/IF($Z10="",1,$Z10))) | AE10: =IF($AH10=0,"",IF($R10="","",D10*$AA10/IF($Z10="",1,$Z10))) | AF10: =IF(R10="","",$AA$4/R10*Q10) -> 15.964166 | AG10: =IF($AH10=0,"",Q10) | AH10: 0 | AI10: =IF(C$6=0,0,SUMIF('Prepool 2'!$X$5:$X$38,X10,'Prepool 2'!$AH$5:$AH$38)*2) -> 2
A11: =IF(INPUTS!A11=0,"none",INPUTS!A11) -> 7050I | B11: =IF(INPUTS!B11=0,"none",INPUTS!B11) -> EF24 | C11: =IF(B11="none",0,MATCH(B11,INPUTS!$B$6:$B$69,0)) -> 6 | D11: =IF($C11=0,"",OFFSET(INPUTS!D$5,$C11,0)) -> 2.39632 | E11: =IF($C11=0,"",OFFSET(INPUTS!E$5,$C11,0)) -> 20 | F11: =IF($C11=0,"",OFFSET(INPUTS!F$5,$C11,0)) -> P4_F05 | G11: =IF($C11=0,"",OFFSET(INPUTS!G$5,$C11,0)) -> 0 | H11: =IF($C11=0,"",OFFSET(INPUTS!H$5,$C11,0)) -> 198 | I11: =IF($C11=0,"",OFFSET(INPUTS!I$5,$C11,0)) -> 0 | J11: =IF($C11=0,"",OFFSET(INPUTS!J$5,$C11,0)) -> 0 | K11: =IF($C11=0,"",OFFSET(INPUTS!K$5,$C11,0)) -> 18.337313 | ... Q11: =IF($C11=0,"",OFFSET(INPUTS!Q$5,$C11,0)) -> 10 | R11: =IF($C11=0,"",$P11-($J11*R$4)) -> 18.337313 | S11: =SUM(J11,R11) -> 18.337313 | T11: =IF(A11=0,"",A11) -> 7050I | U11: =IF(M11=0,"",M11) | V11: =IF(F11=0,"",F11&IF(OR(G11="",G11=0),"","+"&G11)) -> P4_F05 | W11: =IF(ISNUMBER(V11),COUNTIF($V$6:$V$38,V11),"") | X11: =$B11 -> EF24 | Y11: =IF(N11=0,"",N11) | Z11: =IF($AH11=0,"",IF($R11="","",IF(AF11<0.2,10,IF(AF11<0.795,5,"")))) | AA11: =IF($AH11=0,"",IF($R11="","",AF11*IF($Z11="",1,$Z11))) -> 1.6360085 | AB11: =IF(ISNUMBER(AA11),RANK(AA11,$AA$6:$AA$38,0),"") -> 3 | AC11: =IF($AH11=0,"",IF($R11="","",R11*$AA11/IF($Z11="",1,$Z11))) -> 30 | AD11: =IF($AH11=0,"",IF($R11="","",S11*$AA11/IF($Z11="",1,$Z11))) -> 30 | AE11: =IF($AH11=0,"",IF($R11="","",D11*$AA11/IF($Z11="",1,$Z11))) -> 3.9204 | AF11: =IF(R11="","",$AA$4/R11*Q11) -> 1.6360085 | AG11: =IF($AH11=0,"",Q11) -> 10 | AH11: 1 | AI11: =IF(C$6=0,0,SUMIF('Prepool 2'!$X$5:$X$38,X11,'Prepool 2'!$AH$5:$AH$38)*2) -> 0
A12: =IF(INPUTS!A12=0,"none",INPUTS!A12) -> 7050I | B12: =IF(INPUTS!B12=0,"none",INPUTS!B12) -> EF25 | C12: =IF(B12="none",0,MATCH(B12,INPUTS!$B$6:$B$69,0)) -> 7 | D12: =IF($C12=0,"",OFFSET(INPUTS!D$5,$C12,0)) -> 2.53 | E12: =IF($C12=0,"",OFFSET(INPUTS!E$5,$C12,0)) -> 20 | F12: =IF($C12=0,"",OFFSET(INPUTS!F$5,$C12,0)) -> P4_A06 | G12: =IF($C12=0,"",OFFSET(INPUTS!G$5,$C12,0)) -> 0 | H12: =IF($C12=0,"",OFFSET(INPUTS!H$5,$C12,0)) -> 199 | I12: =IF($C12=0,"",OFFSET(INPUTS!I$5,$C12,0)) -> 0 | J12: =IF($C12=0,"",OFFSET(INPUTS!J$5,$C12,0)) -> 0 | K12: =IF($C12=0,"",OFFSET(INPUTS!K$5,$C12,0)) -> 19.262982 | ... Q12: =IF($C12=0,"",OFFSET(INPUTS!Q$5,$C12,0)) -> 100 | R12: =IF($C12=0,"",$P12-($J12*R$4)) -> 19.262982 | S12: =SUM(J12,R12) -> 19.262982 | T12: =IF(A12=0,"",A12) -> 7050I | U12: =IF(M12=0,"",M12) | V12: =IF(F12=0,"",F12&IF(OR(G12="",G12=0),"","+"&G12)) -> P4_A06 | W12: =IF(ISNUMBER(V12),COUNTIF($V$6:$V$38,V12),"") | X12: =$B12 -> EF25 | Y12: =IF(N12=0,"",N12) | Z12: =IF($AH12=0,"",IF($R12="","",IF(AF12<0.2,10,IF(AF12<0.795,5,"")))) | AA12: =IF($AH12=0,"",IF($R12="","",AF12*IF($Z12="",1,$Z12))) | AB12: =IF(ISNUMBER(AA12),RANK(AA12,$AA$6:$AA$38,0),"") | AC12: =IF($AH12=0,"",IF($R12="","",R12*$AA12/IF($Z12="",1,$Z12))) | AD12: =IF($AH12=0,"",IF($R12="","",S12*$AA12/IF($Z12="",1,$Z12))) | AE12: =IF($AH12=0,"",IF($R12="","",D12*$AA12/IF($Z12="",1,$Z12))) | AF12: =IF(R12="","",$AA$4/R12*Q12) -> 15.573913 | AG12: =IF($AH12=0,"",Q12) | AH12: 0 | AI12: =IF(C$6=0,0,SUMIF('Prepool 2'!$X$5:$X$38,X12,'Prepool 2'!$AH$5:$AH$38)*2) -> 2
A13: =IF(INPUTS!A13=0,"none",INPUTS!A13) -> 7050I | B13: =IF(INPUTS!B13=0,"none",INPUTS!B13) -> EF26 | C13: =IF(B13="none",0,MATCH(B13,INPUTS!$B$6:$B$69,0)) -> 8 | D13: =IF($C13=0,"",OFFSET(INPUTS!D$5,$C13,0)) -> 3.3 | E13: =IF($C13=0,"",OFFSET(INPUTS!E$5,$C13,0)) -> 20 | F13: =IF($C13=0,"",OFFSET(INPUTS!F$5,$C13,0)) -> P4_B06 | G13: =IF($C13=0,"",OFFSET(INPUTS!G$5,$C13,0)) -> 0 | H13: =IF($C13=0,"",OFFSET(INPUTS!H$5,$C13,0)) -> 198 | I13: =IF($C13=0,"",OFFSET(INPUTS!I$5,$C13,0)) -> 0 | J13: =IF($C13=0,"",OFFSET(INPUTS!J$5,$C13,0)) -> 0 | K13: =IF($C13=0,"",OFFSET(INPUTS!K$5,$C13,0)) -> 25.252525 | ... Q13: =IF($C13=0,"",OFFSET(INPUTS!Q$5,$C13,0)) -> 10 | R13: =IF($C13=0,"",$P13-($J13*R$4)) -> 25.252525 | S13: =SUM(J13,R13) -> 25.252525 | T13: =IF(A13=0,"",A13) -> 7050I | U13: =IF(M13=0,"",M13) | V13: =IF(F13=0,"",F13&IF(OR(G13="",G13=0),"","+"&G13)) -> P4_B06 | W13: =IF(ISNUMBER(V13),COUNTIF($V$6:$V$38,V13),"") | X13: =$B13 -> EF26 | Y13: =IF(N13=0,"",N13) | Z13: =IF($AH13=0,"",IF($R13="","",IF(AF13<0.2,10,IF(AF13<0.795,5,"")))) | AA13: =IF($AH13=0,"",IF($R13="","",AF13*IF($Z13="",1,$Z13))) -> 1.188 | AB13: =IF(ISNUMBER(AA13),RANK(AA13,$AA$6:$AA$38,0),"") -> 4 | AC13: =IF($AH13=0,"",IF($R13="","",R13*$AA13/IF($Z13="",1,$Z13))) -> 30 | AD13: =IF($AH13=0,"",IF($R13="","",S13*$AA13/IF($Z13="",1,$Z13))) -> 30 | AE13: =IF($AH13=0,"",IF($R13="","",D13*$AA13/IF($Z13="",1,$Z13))) -> 3.9204 | AF13: =IF(R13="","",$AA$4/R13*Q13) -> 1.188 | AG13: =IF($AH13=0,"",Q13) -> 10 | AH13: 1 | AI13: =IF(C$6=0,0,SUMIF('Prepool 2'!$X$5:$X$38,X13,'Prepool 2'!$AH$5:$AH$38)*2) -> 0
A14: =IF(INPUTS!A14=0,"none",INPUTS!A14) -> 7050I | B14: =IF(INPUTS!B14=0,"none",INPUTS!B14) -> EF27 | C14: =IF(B14="none",0,MATCH(B14,INPUTS!$B$6:$B$69,0)) -> 9 | D14: =IF($C14=0,"",OFFSET(INPUTS!D$5,$C14,0)) -> 3.1212 | E14: =IF($C14=0,"",OFFSET(INPUTS!E$5,$C14,0)) -> 20 | F14: =IF($C14=0,"",OFFSET(INPUTS!F$5,$C14,0)) -> P4_C06 | G14: =IF($C14=0,"",OFFSET(INPUTS!G$5,$C14,0)) -> 0 | H14: =IF($C14=0,"",OFFSET(INPUTS!H$5,$C14,0)) -> 197 | I14: =IF($C14=0,"",OFFSET(INPUTS!I$5,$C14,0)) -> 0 | J14: =IF($C14=0,"",OFFSET(INPUTS!J$5,$C14,0)) -> 0 | K14: =IF($C14=0,"",OFFSET(INPUTS!K$5,$C14,0)) -> 24.005538 | ... Q14: =IF($C14=0,"",OFFSET(INPUTS!Q$5,$C14,0)) -> 100 | R14: =IF($C14=0,"",$P14-($J14*R$4)) -> 24.005538 | S14: =SUM(J14,R14) -> 24.005538 | T14: =IF(A14=0,"",A14) -> 7050I | U14: =IF(M14=0,"",M14) | V14: =IF(F14=0,"",F14&IF(OR(G14="",G14=0),"","+"&G14)) -> P4_C06 | W14: =IF(ISNUMBER(V14),COUNTIF($V$6:$V$38,V14),"") | X14: =$B14 -> EF27 | Y14: =IF(N14=0,"",N14) | Z14: =IF($AH14=0,"",IF($R14="","",IF(AF14<0.2,10,IF(AF14<0.795,5,"")))) | AA14: =IF($AH14=0,"",IF($R14="","",AF14*IF($Z14="",1,$Z14))) | AB14: =IF(ISNUMBER(AA14),RANK(AA14,$AA$6:$AA$38,0),"") | AC14: =IF($AH14=0,"",IF($R14="","",R14*$AA14/IF($Z14="",1,$Z14))) | AD14: =IF($AH14=0,"",IF($R14="","",S14*$AA14/IF($Z14="",1,$Z14))) | AE14: =IF($AH14=0,"",IF($R14="","",D14*$AA14/IF($Z14="",1,$Z14))) | AF14: =IF(R14="","",$AA$4/R14*Q14) -> 12.497116 | AG14: =IF($AH14=0,"",Q14) | AH14: 0 | AI14: =IF(C$6=0,0,SUMIF('Prepool 2'!$X$5:$X$38,X14,'Prepool 2'!$AH$5:$AH$38)*2) -> 2
A15: =IF(INPUTS!A15=0,"none",INPUTS!A15) -> 7050I | B15: =IF(INPUTS!B15=0,"none",INPUTS!B15) -> EF28 | C15: =IF(B15="none",0,MATCH(B15,INPUTS!$B$6:$B$69,0)) -> 10 | D15: =IF($C15=0,"",OFFSET(INPUTS!D$5,$C15,0)) -> 0.1 | E15: =IF($C15=0,"",OFFSET(INPUTS!E$5,$C15,0)) -> 20 | F15: =IF($C15=0,"",OFFSET(INPUTS!F$5,$C15,0)) -> P4_D06 | G15: =IF($C15=0,"",OFFSET(INPUTS!G$5,$C15,0)) -> 0 | H15: =IF($C15=0,"",OFFSET(INPUTS!H$5,$C15,0)) -> 198 | I15: =IF($C15=0,"",OFFSET(INPUTS!I$5,$C15,0)) -> 0 | J15: =IF($C15=0,"",OFFSET(INPUTS!J$5,$C15,0)) -> 0 | K15: =IF($C15=0,"",OFFSET(INPUTS!K$5,$C15,0)) -> 0.76522804 | ... Q15: =IF($C15=0,"",OFFSET(INPUTS!Q$5,$C15,0)) -> 10 | R15: =IF($C15=0,"",$P15-($J15*R$4)) -> 0.76522804 | S15: =SUM(J15,R15) -> 0.76522804 | T15: =IF(A15=0,"",A15) -> 7050I | U15: =IF(M15=0,"",M15) | V15: =IF(F15=0,"",F15&IF(OR(G15="",G15=0),"","+"&G15)) -> P4_D06 | W15: =IF(ISNUMBER(V15),COUNTIF($V$6:$V$38,V15),"") | X15: =$B15 -> EF28 | Y15: =IF(N15=0,"",N15) | Z15: =IF($AH15=0,"",IF($R15="","",IF(AF15<0.2,10,IF(AF15<0.795,5,"")))) | AA15: =IF($AH15=0,"",IF($R15="","",AF15*IF($Z15="",1,$Z15))) | AB15: =IF(ISNUMBER(AA15),RANK(AA15,$AA$6:$AA$38,0),"") | AC15: =IF($AH15=0,"",IF($R15="","",R15*$AA15/IF($Z15="",1,$Z15))) | AD15: =IF($AH15=0,"",IF($R15="","",S15*$AA15/IF($Z15="",1,$Z15))) | AE15: =IF($AH15=0,"",IF($R15="","",D15*$AA15/IF($Z15="",1,$Z15))) | AF15: =IF(R15="","",$AA$4/R15*Q15) -> 39.204 | AG15: =IF($AH15=0,"",Q15) | AH15: 0 | AI15: =IF(C$6=0,0,SUMIF('Prepool 2'!$X$5:$X$38,X15,'Prepool 2'!$AH$5:$AH$38)*2) -> 2
A16: =IF(INPUTS!A16=0,"none",INPUTS!A16) -> 7050I | B16: =IF(INPUTS!B16=0,"none",INPUTS!B16) -> EF29 | C16: =IF(B16="none",0,MATCH(B16,INPUTS!$B$6:$B$69,0)) -> 11 | D16: =IF($C16=0,"",OFFSET(INPUTS!D$5,$C16,0)) -> 0.1 | E16: =IF($C16=0,"",OFFSET(INPUTS!E$5,$C16,0)) -> 20 | F16: =IF($C16=0,"",OFFSET(INPUTS!F$5,$C16,0)) -> P4_E06 | G16: =IF($C16=0,"",OFFSET(INPUTS!G$5,$C16,0)) -> 0 | H16: =IF($C16=0,"",OFFSET(INPUTS!H$5,$C16,0)) -> 196 | I16: =IF($C16=0,"",OFFSET(INPUTS!I$5,$C16,0)) -> 0 | J16: =IF($C16=0,"",OFFSET(INPUTS!J$5,$C16,0)) -> 0 | K16: =IF($C16=0,"",OFFSET(INPUTS!K$5,$C16,0)) -> 0.77303649 | ... Q16: =IF($C16=0,"",OFFSET(INPUTS!Q$5,$C16,0)) -> 100 | R16: =IF($C16=0,"",$P16-($J16*R$4)) -> 0.77303649 | S16: =SUM(J16,R16) -> 0.77303649 | T16: =IF(A16=0,"",A16) -> 7050I | U16: =IF(M16=0,"",M16) | V16: =IF(F16=0,"",F16&IF(OR(G16="",G16=0),"","+"&G16)) -> P4_E06 | W16: =IF(ISNUMBER(V16),COUNTIF($V$6:$V$38,V16),"") | X16: =$B16 -> EF29 | Y16: =IF(N16=0,"",N16) | Z16: =IF($AH16=0,"",IF($R16="","",IF(AF16<0.2,10,IF(AF16<0.795,5,"")))) | AA16: =IF($AH16=0,"",IF($R16="","",AF16*IF($Z16="",1,$Z16))) | AB16: =IF(ISNUMBER(AA16),RANK(AA16,$AA$6:$AA$38,0),"") | AC16: =IF($AH16=0,"",IF($R16="","",R16*$AA16/IF($Z16="",1,$Z16))) | AD16: =IF($AH16=0,"",IF($R16="","",S16*$AA16/IF($Z16="",1,$Z16))) | AE16: =IF($AH16=0,"",IF($R16="","",D16*$AA16/IF($Z16="",1,$Z16))) | AF16: =IF(R16="","",$AA$4/R16*Q16) -> 388.08 | AG16: =IF($AH16=0,"",Q16) | AH16: 0 | AI16: =IF(C$6=0,0,SUMIF('Prepool 2'!$X$5:$X$38,X16,'Prepool 2'!$AH$5:$AH$38)*2) -> 0
A17: =IF(INPUTS!A17=0,"none",INPUTS!A17) -> 7050I | B17: =IF(INPUTS!B17=0,"none",INPUTS!B17) -> EF30 | C17: =IF(B17="none",0,MATCH(B17,INPUTS!$B$6:$B$69,0)) -> 12 | D17: =IF($C17=0,"",OFFSET(INPUTS!D$5,$C17,0)) -> 0.1 | E17: =IF($C17=0,"",OFFSET(INPUTS!E$5,$C17,0)) -> 20 | F17: =IF($C17=0,"",OFFSET(INPUTS!F$5,$C17,0)) -> P4_F06 | G17: =IF($C17=0,"",OFFSET(INPUTS!G$5,$C17,0)) -> 0 | H17: =IF($C17=0,"",OFFSET(INPUTS!H$5,$C17,0)) -> 197 | I17: =IF($C17=0,"",OFFSET(INPUTS!I$5,$C17,0)) -> 0 | J17: =IF($C17=0,"",OFFSET(INPUTS!J$5,$C17,0)) -> 0 | K17: =IF($C17=0,"",OFFSET(INPUTS!K$5,$C17,0)) -> 0.76911244 | ... Q17: =IF($C17=0,"",OFFSET(INPUTS!Q$5,$C17,0)) -> 10 | R17: =IF($C17=0,"",$P17-($J17*R$4)) -> 0.76911244 | S17: =SUM(J17,R17) -> 0.76911244 | T17: =IF(A17=0,"",A17) -> 7050I | U17: =IF(M17=0,"",M17) | V17: =IF(F17=0,"",F17&IF(OR(G17="",G17=0),"","+"&G17)) -> P4_F06 | W17: =IF(ISNUMBER(V17),COUNTIF($V$6:$V$38,V17),"") | X17: =$B17 -> EF30 | Y17: =IF(N17=0,"",N17) | Z17: =IF($AH17=0,"",IF($R17="","",IF(AF17<0.2,10,IF(AF17<0.795,5,"")))) | AA17: =IF($AH17=0,"",IF($R17="","",AF17*IF($Z17="",1,$Z17))) | AB17: =IF(ISNUMBER(AA17),RANK(AA17,$AA$6:$AA$38,0),"") | AC17: =IF($AH17=0,"",IF($R17="","",R17*$AA17/IF($Z17="",1,$Z17))) | AD17: =IF($AH17=0,"",IF($R17="","",S17*$AA17/IF($Z17="",1,$Z17))) | AE17: =IF($AH17=0,"",IF($R17="","",D17*$AA17/IF($Z17="",1,$Z17))) | AF17: =IF(R17="","",$AA$4/R17*Q17) -> 39.006 | AG17: =IF($AH17=0,"",Q17) | AH17: 0 | AI17: =IF(C$6=0,0,SUMIF('Prepool 2'!$X$5:$X$38,X17,'Prepool 2'!$AH$5:$AH$38)*2) -> 2
... A38: =IF(INPUTS!A38=0,"none",INPUTS!A38) -> none | B38: =IF(INPUTS!B38=0,"none",INPUTS!B38) -> none | C38: =IF(B38="none",0,MATCH(B38,INPUTS!$B$6:$B$69,0)) -> 0 | D38: =IF($C38=0,"",OFFSET(INPUTS!D$5,$C38,0)) | E38: =IF($C38=0,"",OFFSET(INPUTS!E$5,$C38,0)) | F38: =IF($C38=0,"",OFFSET(INPUTS!F$5,$C38,0)) | G38: =IF($C38=0,"",OFFSET(INPUTS!G$5,$C38,0)) | H38: =IF($C38=0,"",OFFSET(INPUTS!H$5,$C38,0)) | I38: =IF($C38=0,"",OFFSET(INPUTS!I$5,$C38,0)) | J38: =IF($C38=0,"",OFFSET(INPUTS!J$5,$C38,0)) | K38: =IF($C38=0,"",OFFSET(INPUTS!K$5,$C38,0)) | ... Q38: =IF($C38=0,"",OFFSET(INPUTS!Q$5,$C38,0)) | R38: =IF($C38=0,"",$P38-($J38*R$4)) | S38: =SUM(J38,R38) -> 0 | T38: =IF(A38=0,"",A38) -> none | U38: =IF(M38=0,"",M38) | V38: =IF(F38=0,"",F38&IF(OR(G38="",G38=0),"","+"&G38)) | W38: =IF(ISNUMBER(V38),COUNTIF($V$6:$V$38,V38),"") | X38: =$B38 -> none | Y38: =IF(N38=0,"",N38) | Z38: =IF($AH38=0,"",IF($R38="","",IF(AF38<0.2,10,IF(AF38<0.795,5,"")))) | AA38: =IF($AH38=0,"",IF($R38="","",AF38*IF($Z38="",1,$Z38))) | AB38: =IF(ISNUMBER(AA38),RANK(AA38,$AA$6:$AA$38,0),"") | AC38: =IF($AH38=0,"",IF($R38="","",R38*$AA38/IF($Z38="",1,$Z38))) | AD38: =IF($AH38=0,"",IF($R38="","",S38*$AA38/IF($Z38="",1,$Z38))) | AE38: =IF($AH38=0,"",IF($R38="","",D38*$AA38/IF($Z38="",1,$Z38))) | AF38: =IF(R38="","",$AA$4/R38*Q38) | AG38: =IF($AH38=0,"",Q38) | AH38: 0 | AI38: =IF(C$6=0,0,SUMIF('Prepool 2'!$X$5:$X$38,X38,'Prepool 2'!$AH$5:$AH$38)*2) -> 0
AA39: =SUM(AA6:AA38) -> 6.8329489 | AC39: =SUM(AC6:AC38) -> 120 | AD39: =SUM(AD6:AD38) -> 120 | AE39: =SUM(AE6:AE38) -> 15.642
L40: avg | P40: =IF(ISERROR(AVERAGE(P6:P38)),0,AVERAGE(P6:P38)) -> 13.707469 | Q40: =IF(ISERROR(AVERAGE(Q6:Q38)),0,AVERAGE(Q6:Q38)) -> 55
Z41: Lib vol | AA41: =SUM(AA6:AA38) -> 6.8329489 | AB41: ul
Z42: 0.1x TE buffer | AA42: =AC42 -> 0 | AB42: ul | AC42: 0 | AD42: add TT
Z43: Prepool vol | AA43: =SUM(AA41:AA42) -> 6.8329489 | AB43: ul
Z44: Prepool nM | AA44: =IF($AA$41=0,"",AC39/$AA$43) -> 17.561964 | AB44: adj lib
Z45: Prepool nM | AA45: =IF($AA$41=0,"",AD39/$AA$43) -> 17.561964 | AB45: total
Z46: Prepool ng/ul | AA46: =IF($AA$41=0,"",AE39/$AA$43) -> 2.2892019 | AB46: total
Z47: # libraries | AA47: =COUNTIF(AG6:AG38,">0") -> 4
T50: filter on Project <> none

Sheet Prepool 2
T1: Prepool 2
A2: Don’t add libraries here -- only add on INPUTS sheet! Filter this sheet for printing (no need to delete rows) | T2: ='Final Pool'!$T$2 -> 45982 | Z2: =COUNT(Z6:Z39) -> 0 | AA2: =COUNTIF(AA6:AA39,">2") -> 7 | AH2: Select Libs Here
D3: Final Library | O3: =INPUTS!O3 -> Empirical | P3: =INPUTS!P3 -> Use | R3: AdDimer adjust | X3: Final Lib | AA3: Pool | AH3: include | AI3: included
B4: Lib | D4: =INPUTS!D4 -> Final | E4: =INPUTS!E4 -> Total | I4: =INPUTS!I4 -> lowMW=primer | J4: =INPUTS!J4 -> AdDimer | K4: =INPUTS!K4 -> Library | L4: =INPUTS!L4 -> Total | O4: =INPUTS!O4 -> Library | P4: =INPUTS!P4 -> Library | Q4: Final pool | R4: 0.05 | V4: =COUNTIF(W6:W38,">1") -> 0 | Z4: pre-dil | AA4: 0.4 | AG4: target | AH4: in this | AI4: in
A5: Project ID | B5: Name | C5: match | D5: =INPUTS!D5 -> ng/ul | E5: =INPUTS!E5 -> vol | F5: =INPUTS!F5 -> UDI: Plate_Well | G5: =INPUTS!G5 -> notes | H5: =INPUTS!H5 -> Adj peak size | I5: =INPUTS!I5 -> %ofLib | J5: =INPUTS!J5 -> nM | K5: =INPUTS!K5 -> nM | ... Q5: =INPUTS!Q5 -> Reads (M) | R5: Adj lib nM | S5: tot nM | T5: Project# | U5: Lib# | V5: BC | X5: name | Y5: Loc | AA5: vol | AC5: adj lib pmol | AD5: tot pmol | AE5: total ng | AF5: stock vol | AG5: M reads | AH5: Prepool | AI5: Prepool 1
A6: =IF(INPUTS!A6=0,"none",INPUTS!A6) -> 7050I | B6: =IF(INPUTS!B6=0,"none",INPUTS!B6) -> EF19 | C6: =IF(B6="none",0,MATCH(B6,INPUTS!$B$6:$B$69,0)) -> 1 | D6: =IF($C6=0,"",OFFSET(INPUTS!D$5,$C6,0)) -> 1.7766 | E6: =IF($C6=0,"",OFFSET(INPUTS!E$5,$C6,0)) -> 20 | F6: =IF($C6=0,"",OFFSET(INPUTS!F$5,$C6,0)) -> P4_A05 | G6: =IF($C6=0,"",OFFSET(INPUTS!G$5,$C6,0)) -> 0 | H6: =IF($C6=0,"",OFFSET(INPUTS!H$5,$C6,0)) -> 198 | I6: =IF($C6=0,"",OFFSET(INPUTS!I$5,$C6,0)) -> 0 | J6: =IF($C6=0,"",OFFSET(INPUTS!J$5,$C6,0)) -> 0 | K6: =IF($C6=0,"",OFFSET(INPUTS!K$5,$C6,0)) -> 13.595041 | ... Q6: =IF($C6=0,"",OFFSET(INPUTS!Q$5,$C6,0)) -> 100 | R6: =IF($C6=0,"",$P6-($J6*R$4)) -> 13.595041 | S6: =SUM(J6,R6) -> 13.595041 | T6: =IF(A6=0,"",A6) -> 7050I | U6: =IF(M6=0,"",M6) | V6: =IF(F6=0,"",F6&IF(OR(G6="",G6=0),"","+"&G6)) -> P4_A05 | W6: =IF(ISNUMBER(V6),COUNTIF($V$6:$V$38,V6),"") | X6: =$B6 -> EF19 | Y6: =IF(N6=0,"",N6) | Z6: =IF($AH6=0,"",IF($R6="","",IF(AF6<0.2,10,IF(AF6<0.795,5,"")))) | AA6: =IF($AH6=0,"",IF($R6="","",AF6*IF($Z6="",1,$Z6))) -> 2.9422492 | AB6: =IF(ISNUMBER(AA6),RANK(AA6,$AA$6:$AA$38,0),"") -> 4 | AC6: =IF($AH6=0,"",IF($R6="","",R6*$AA6/IF($Z6="",1,$Z6))) -> 40 | AD6: =IF($AH6=0,"",IF($R6="","",S6*$AA6/IF($Z6="",1,$Z6))) -> 40 | AE6: =IF($AH6=0,"",IF($R6="","",D6*$AA6/IF($Z6="",1,$Z6))) -> 5.2272 | AF6: =IF(R6="","",$AA$4/R6*Q6) -> 2.9422492 | AG6: =IF($AH6=0,"",Q6) -> 100 | AH6: 1 | AI6: =IF(C$6=0,0,SUMIF('Prepool 1'!$X$5:$X$38,X6,'Prepool 1'!$AH$5:$AH$38)) -> 0
A7: =IF(INPUTS!A7=0,"none",INPUTS!A7) -> 7050I | B7: =IF(INPUTS!B7=0,"none",INPUTS!B7) -> EF20 | C7: =IF(B7="none",0,MATCH(B7,INPUTS!$B$6:$B$69,0)) -> 2 | D7: =IF($C7=0,"",OFFSET(INPUTS!D$5,$C7,0)) -> 1.70372 | E7: =IF($C7=0,"",OFFSET(INPUTS!E$5,$C7,0)) -> 20 | F7: =IF($C7=0,"",OFFSET(INPUTS!F$5,$C7,0)) -> P4_B05 | G7: =IF($C7=0,"",OFFSET(INPUTS!G$5,$C7,0)) -> 0 | H7: =IF($C7=0,"",OFFSET(INPUTS!H$5,$C7,0)) -> 198 | I7: =IF($C7=0,"",OFFSET(INPUTS!I$5,$C7,0)) -> 0 | J7: =IF($C7=0,"",OFFSET(INPUTS!J$5,$C7,0)) -> 0 | K7: =IF($C7=0,"",OFFSET(INPUTS!K$5,$C7,0)) -> 13.037343 | ... Q7: =IF($C7=0,"",OFFSET(INPUTS!Q$5,$C7,0)) -> 10 | R7: =IF($C7=0,"",$P7-($J7*R$4)) -> 13.037343 | S7: =SUM(J7,R7) -> 13.037343 | T7: =IF(A7=0,"",A7) -> 7050I | U7: =IF(M7=0,"",M7) | V7: =IF(F7=0,"",F7&IF(OR(G7="",G7=0),"","+"&G7)) -> P4_B05 | W7: =IF(ISNUMBER(V7),COUNTIF($V$6:$V$38,V7),"") | X7: =$B7 -> EF20 | Y7: =IF(N7=0,"",N7) | Z7: =IF($AH7=0,"",IF($R7="","",IF(AF7<0.2,10,IF(AF7<0.795,5,"")))) | AA7: =IF($AH7=0,"",IF($R7="","",AF7*IF($Z7="",1,$Z7))) | AB7: =IF(ISNUMBER(AA7),RANK(AA7,$AA$6:$AA$38,0),"") | AC7: =IF($AH7=0,"",IF($R7="","",R7*$AA7/IF($Z7="",1,$Z7))) | AD7: =IF($AH7=0,"",IF($R7="","",S7*$AA7/IF($Z7="",1,$Z7))) | AE7: =IF($AH7=0,"",IF($R7="","",D7*$AA7/IF($Z7="",1,$Z7))) | AF7: =IF(R7="","",$AA$4/R7*Q7) -> 0.30681098 | AG7: =IF($AH7=0,"",Q7) | AH7: 0 | AI7: =IF(C$6=0,0,SUMIF('Prepool 1'!$X$5:$X$38,X7,'Prepool 1'!$AH$5:$AH$38)) -> 1
